Workbook

Sheet Instrucciones
A1: Diagnóstico de restauración
A2: Versión 2.0 - Actualizado en 2026
B4: Informacion general | H4: ¿Cómo funciona el diagnóstico? | N4: Otras consideraciones
B5: ¡Bienvenido al diagnóstico de restauración de WRI! Una herramienta de evaluación rápida para valorar la preparación de una zona geográfica o escala para la restauración y diseñar acciones estratégicas que garanticen el éxito a largo plazo. Una herramienta independiente desarrollada como parte de ROAM (Metodología de evaluación de oportunidades de restauración) https://iucn.org/resources/grey-literature/guide-restoration-opportunities-assessment-methodology-roam | H5: El diagnóstico sigue un proceso de tres pasos; se recomienda encarecidamente leer la sección anterior antes de empezar. Además, se sugiere un paso preparatorio. Consulte la pestaña "Antes de empezar". Cada paso corresponde a una sección de la herramienta, y cada uno de ellos se explica en una pestaña independiente de este documento: Paso 1. Definir el alcance; Paso 2. Evaluar los factores clave para la restauración; Paso 3. Proponer estrategias para subsanar las deficiencias La pestaña «Tabla resumen» genera una tabla resumen basada en los datos introducidos en los pasos 1, 2 y 3. | N5: Cronograma sugerido para la aplicación del diagnóstico Paso 1. Definir el alcance 2-3 días Paso 2. Evaluar los factores clave para la restauración 2-4 semanas Paso 3. Seleccionar acciones para abordar las deficiencias. 2-3 semanas El cronograma sugerido proporciona una estimación indicativa del tiempo necesario para aplicar el diagnóstico. La duración real puede variar en función del contexto, el alcance de la evaluación, la disponibilidad de información, los procesos de participación de las partes interesadas y el tiempo asignado por el equipo de ejecución. En algunos casos, las etapas pueden prolongarse si es necesario realizar consultas adicionales, recopilar datos o llevar a cabo procesos de validación. Por el contrario, el proceso puede avanzar más rápidamente cuando se dispone fácilmente de información y de las partes interesadas.
B10: ¿Qué es la herramienta de diagnóstico de restauración? El Diagnóstico de Restauración te ayuda a evaluar si se dan los factores clave culturales, financieros, políticos, institucionales y ecológicos necesarios para que la restauración de los ecosistemas prospere. Al identificar las carencias y los retos, podrás pasar de una planificación general a una actuación específica y eficaz.
B14: ¿Por qué es útil esta herramienta? Un diagnóstico ayuda a identificar los factores clave que influyen en el éxito de la restauración y permite planificar y actuar de forma más estratégica.
B17: ¿Soy la persona adecuada para utilizar esta herramienta? Deberías utilizar esta herramienta si te encargas de planificar o coordinar políticas, acciones y medidas de restauración a nivel nacional o regional y deseas conocer las condiciones actuales necesarias para llevar a cabo una restauración satisfactoria.
N19: ¿Cuál es el resultado final de este diagnóstico? El diagnóstico permite llegar a un consenso sobre los factores clave que influyen en el éxito de la restauración y establecer un conjunto de medidas priorizadas para reforzar dichos factores y hacer posible la restauración en la zona o a la escala previstas.
H21: La columna "Orientación adicional" ofrece más detalles sobre cada factor clave para orientar sus respuestas en el paso 2.
B22: Nota sobre la participación: Si bien una sola persona puede encargarse de la introducción de datos, la herramienta resulta más eficaz cuando se utiliza de forma participativa, recabando perspectivas de diversos interesados y expertos.
B27: ¿Cuáles son los factores clave? Los factores clave son las condiciones y los elementos que influyen en el éxito y la sostenibilidad a largo plazo de las iniciativas de restauración. Por ejemplo, entre estos factores se incluyen los beneficios que aporta la restauración, los conocimientos disponibles sobre la restauración, las condiciones del mercado y las políticas relacionadas con la restauración, entre otros. A modo de referencia, en el paso 2 se incluye una lista completa de las condiciones propicias y los factores clave.
N29: Documentos a recopilar con antelación (lista no exhaustiva) +Planes, estrategias o programas nacionales de restauración +Compromisos de restauración en el marco de la CDB y la CMNUCC +Leyes o políticas relacionadas con la restauración forestal, agrícola u otros ecosistemas pertinentes +Documentación subnacional de las acciones de restauración +Planes de desarrollo municipal en los paisajes objetivo
H30: Si necesita más información sobre cómo se ha elaborado esta herramienta, puede consultar una explicación detallada por escrito del diagnóstico en línea en: XXXX
B35: Uso de los datos: Sus datos se utilizarán de conformidad con la Política de Privacidad de WRI, que puede consultarse en el siguiente enlace: https://www.wri.org/about/privacy-policy. Nos gustaría destacar que puede interactuar con WRI en línea a través de diversos sitios web, aplicaciones, herramientas de diagnóstico, herramientas digitales, encuestas, correos electrónicos, páginas en redes sociales y otros servicios en línea mediante los cuales llevamos a cabo investigaciones, actividades programáticas, comunicaciones o iniciativas de participación (en conjunto, los "Servicios").

Sheet Antes de empezar
B1: Antes de empezar
B3: Antes de empezar
B4: ¿Por qué completar esta fase? Esta fase de preparación contribuye a garantizar que el diagnóstico se desarrolle sin contratiempos y arroje resultados en los que las partes interesadas confíen y sobre los que puedan actuar. Esto ayuda a garantizar: Alineación: Las funciones y responsabilidades están claras. Inclusión: Se cuenta con la participación de las partes interesadas pertinentes. Eficiencia: La información y los documentos esenciales ya están listos.
B6: Cómo completar esta fase
B7: 1. Nombrar a un responsable del proceso Designar a una persona encargada de coordinar el diagnóstico y de recopilar los resultados. 2. Definir la participación de las partes interesadas Elija cómo las partes interesadas contribuirán a: Talleres para debates grupales y puesta en común rápida Entrevistas sobre temas determinados Aportaciones a distancia de expertos técnicos que colaboran de forma remota 3. Recopilar materiales clave Recopilar documentos y datos relevantes que respalden la evaluación
B9: Diseño de la participación de las partes interesadas
B10: Empieza por analizar el panorama social en torno a la restauración: quiénes son los usuarios, quiénes se ven afectados y quiénes tienen influencia. Identifica las necesidades, las motivaciones y las relaciones de las partes interesadas para comprender dónde pueden surgir fricciones o puntos de coincidencia. Aprovecha esta información para diseñar puntos de contacto —talleres, entrevistas, procesos de retroalimentación— que sean inclusivos, iterativos y se adapten al contexto. Trata a las partes interesadas como co-diseñadores, y no solo como fuentes de datos, para mejorar la facilidad de uso, la relevancia y la aceptación de la herramienta. Herramienta recomendada para cartografiar los paisajes sociales: https://www.wri.org/research/mapping-social-landscapes-guide-identifying-networks-priorities-and-values-restoration
B17: Documentos que se recomienda reunir (lista no exhaustiva)
B18: □ A. Contexto normativo y jurídico [ ] Estrategias o programas nacionales de restauración. [ ] Leyes y reglamentos (silvicultura, agricultura, ordenación del territorio, recursos hídricos). [ ] Compromisos internacionales (CMNUCC, CDB, CNULD). [ ] Planes nacionales de desarrollo y contribuciones nacionalmente determinadas (NDC). □ B. Ejecución y planificación [ ] Planes de acción de restauración a nivel subnacional o regional. [ ] Planes de desarrollo municipal para los paisajes en cuestión. [ ] Documentación de programas financiados por donantes. [ ] Presupuestos institucionales y organigramas existentes. □ C. Datos biofísicos y socioeconómicos [ ] Evaluaciones de la cobertura del suelo y la degradación del suelo. [ ] Mapas de oportunidades de restauración (por ejemplo, resultados de ROAM). [ ] Datos socioeconómicos (situación de tenencia, dependencia de los medios de subsistencia, análisis de mercado). □ D. Seguimiento y valores de referencia [ ] Datos procedentes de sistemas de seguimiento del paisaje (por ejemplo, Global Forest Watch). [ ] Indicadores de restauración existentes e informes de progreso históricos.
B20: Garantizar la inclusión y la equidad
B21: Es posible que algunos participantes se muestren reacios a intervenir en los debates en grupo y las dinámicas sociales y de género locales pueden excluir a ciertos grupos. El equipo coordinador debería adaptar los métodos de participación para garantizar que se tengan en cuenta perspectivas diversas. Esto se puede hacer de la siguiente manera: • organizar grupos de discusión separados para mujeres y/o comunidades indígenas • utilizar las lenguas locales • contar con la participación de intermediarios de confianza • ofrecer ayuda para los desplazamientos o una compensación económica cuando sea necesario • establecer acuerdos para garantizar un espacio seguro • permitir la participación anónima por escrito en el caso de preguntas delicadas

Sheet Paso 1. Definir el alcance
B1: Paso 1. Definir el alcance
B3: ¿Por qué es importante este paso?
B4: En este paso, puedes dedicar un tiempo a definir claramente el alcance de la evaluación. Esto incluye decidir dónde se llevará a cabo el diagnóstico, el plazo previsto y los objetivos de la restauración del paisaje. Tomar estas decisiones desde el principio ayuda a garantizar que el diagnóstico se centre en los aspectos, las partes interesadas y las oportunidades de recuperación adecuados.
B7: Selecciona la zona geográfica y los tipos de ecosistema
B8: Defina el entorno geográfico, la escala o el paisaje en el que se llevará a cabo el diagnóstico. Es importante seleccionar el ámbito geográfico adecuado, ya que determina qué ecosistemas se evaluarán, qué partes interesadas deben participar y qué opciones de restauración son pertinentes. Esto puede incluir: Nacional Subnacional (es decir, municipio, provincia, distrito) Paisaje (o paisaje marino, si procede) Zona de restauración Transfronterizo (es decir, dos o más países)
B14: Captura los tipos de ecosistema
B15: La siguiente lista de ecosistemas es orientativa.
B16: Referencia: Tipología Global de Ecosistemas de la UICN 2.0
B17: https://portals.iucn.org/library/sites/library/files/documents/2020-037-En.pdf, https://global-ecosystems.org/
B18: Terrestre | F18: Agua dulce | I18: Marino
B19: Bosques tropicales y subtropicales | F19: Turberas | I19: Plataformas marinas
B20: Bosques y zonas boscosas templadas y boreales | F20: Humedales | I20: Manglares y sistemas costeros
B21: Matorrales y bosques arbustivos | F21: Ecosistemas ribereños | I21: Fondos marinos profundos
B22: Sabanas y praderas | F22: Cuencas hidrográficas
B23: Desiertos y semidesiertos | F23: Aguas dulces artificiales
B24: Polar-alpino
B25: Sistemas productivos y agrícolas
B26: Paisajes urbanos
B28: Establecer el horizonte temporal
B29: Decide hasta qué punto en el futuro se prevé que llegue el proyecto de restauración. La restauración es un proceso a largo plazo. Aunque algunos beneficios pueden aparecer pronto, muchos resultados ecológicos y sociales tardan años en materializarse. Establecer un plazo claro ayuda a fijar expectativas realistas y garantiza que las iniciativas de restauración se ajusten a las políticas y los ciclos de planificación existentes. Apuesta por una visión a largo plazo, aunque las medidas se pongan en marcha a corto plazo. Siempre que sea posible, hay que ajustar el cronograma a los marcos de planificación nacionales o regionales.
B31: Definir los objetivos de restauración
B32: Aclara qué es lo que quieres conseguir con la restauración del paisaje. Los objetivos de restauración pueden centrarse en un único ecosistema (como los bosques o los manglares) o en una combinación de ecosistemas y usos del suelo, incluidos los sistemas agrícolas o agroforestales. Los objetivos pueden describirse tanto antes como después de ejecutar el diagnóstico, dependiendo del contexto y de cómo se lleve a cabo dicho diagnóstico. Entre los objetivos habituales de la restauración se incluyen (lista no exhaustiva): - Conservación de la biodiversidad - Mitigación o adaptación al cambio climático - Mejora de los medios de vida - Seguridad hídrica - Producción alimentaria Unos objetivos claramente definidos ayudan a determinar qué opciones de restauración se tienen en cuenta y facilitan que las partes interesadas se pongan de acuerdo sobre cómo se definirá el éxito.
B34: Validar el alcance con las partes interesadas
B35: Antes de continuar, confirme el alcance con las partes interesadas pertinentes. Una validación temprana contribuye a generar confianza, un entendimiento común y un sentido de implicación en el proceso de diagnóstico. Además, contribuye a garantizar que la evaluación refleje las prioridades y realidades locales.

Sheet Paso 2. Evaluar los factores
A1: Paso 2. Evalúa los factores clave para la restauración seleccionando una respuesta para cada una de las preguntas siguientes. Se ofrece una definición y una serie de preguntas complementarias para recabar más información
B3: Objetivo En el paso 2 se evalúa si los factores clave para el éxito de la restauración de los ecosistemas están actualmente: • En funcionamiento • Parcialmente en funcionamiento • No en funcionamiento El objetivo no es realizar un análisis exhaustivo de cada aspecto del proceso de restauración, sino identificar rápidamente las fortalezas, las debilidades y los posibles obstáculos para una restauración exitosa. Estructura de la evaluación La evaluación se articula en torno a tres temas generales: 1. Motivar: factores que inspiran o motivan para impulsar procesos que conducen a la restauración 2. Habilitar: factores que crean un contexto favorable para la restauración 3. Implementar: factores relacionados con las capacidades y los recursos para movilizar la implementación de las medidas de restauración sobre el terreno | K3: El código de colores significa lo siguiente:
K4: Verde = EN FUNCIONAMIENTO
K5: Amarillo = PARCIALMENTE EN FUNCIONAMIENTO
K6: Rojo = NO EN FUNCIONAMIENTO
K7: Blanco: NO APLICABLE
B12: Condición habilitante | C12: Factor clave | D12: Pregunta | E12: Respuesta | F12: Nacional | G12: Regional | H12: Local | I12: Definición | J12: Orientación | K12: Pregunta(s) complementaria(s) | L12: Respuestas complementarias, justificación y documentos de soporte
A13: Motivar | B13: a. Beneficios | C13: 1. La restauración genera beneficios económicos | D13: • ¿Se espera que la restauración del área objetivo genere beneficios económicos que resulten en un impacto neto positivo financiero o económico a nivel de toda la economía en relación con el uso actual de la tierra? | I13: Se espera que la restauración del área objetivo produzca beneficios económicos (por ejemplo, diversificación económica, daños evitados, nuevos productos comercializables) que creen un impacto financiero neto positivo (beneficios privados) y/o un impacto neto positivo en toda la economía (beneficios públicos) en relación con el uso de la tierra actual. Nota al margen: “impactos económicos que se refieren a los beneficios ambientales que funcionan como bienes públicos, o a los impactos económicos en toda la economía que capturan los efectos indirectos relacionados con la restauración en las cadenas de valor y la economía en general, incluido el crecimiento del PIB y el empleo. Estos impactos suelen surgir de beneficios económicos como la diversificación, los daños evitados y los nuevos productos de mercado posibilitados por la restauración. | J13: • Los beneficios económicos de la restauración son los resultados positivos globales para los ingresos o las finanzas que se derivan de la aplicación de actividades de restauración frente a un escenario sin cambios. • Algunos ejemplos de beneficios económicos incluyen un mayor ingreso, mejores oportunidades empresariales, una mayor producción de productos básicos clave o nuevas oportunidades de empleo que resultan de los esfuerzos de restauración. Una lista más completa de posibles beneficios se incluye en esta herramienta en la tabla “Beneficios de la Restauración”. • El marco temporal de esta respuesta debe considerar el cronograma de las actividades de restauración previstas, reconociendo que los procesos de restauración y sus beneficios ocurren en el largo plazo. • Siempre que sea posible, distinga entre los beneficios a corto, mediano y largo plazo, incluidos los resultados esperados una vez que la restauración se haya implementado por completo. • Tome nota de qué personas o grupos probablemente recibirían estos beneficios. • Algunos propietarios de tierras pueden estar preocupados de que la “restauración” signifique que perderán sus tierras, sus derechos de uso o sus ingresos en relación con el statu quo. Por lo tanto, la respuesta a esta pregunta puede respaldarse con documentos que muestren cómo los beneficios netos superan los costos. Nota al margen: los derechos territoriales formalizados podrían surgir como un cobeneficio positivo del proyecto de restauración. En algunos casos, la implementación del proyecto y el desembolso de fondos para apoyar las actividades de restauración pueden requerir que se definan claramente derechos sobre la tierra. En consecuencia, esto podría acelerar los procesos de demarcación y permitir que las comunidades locales obtengan títulos legales sobre sus tierras. | K13: • Si la respuesta es “sí”, ¿cuáles son los beneficios económicos esperados? • Si la respuesta es “sí”, ¿quién se beneficia? • Si la respuesta es “no”, ¿cuál es la magnitud de la brecha financiera o económica prevista?
C14: 2. La restauración genera beneficios sociales | D14: • ¿Se espera que la restauración del área objetivo genere beneficios sociales, culturales o políticos para las personas que viven en esa área, incluidos los grupos de mujeres, los jóvenes y los pueblos indígenas? | I14: Se espera que la restauración del área objetivo mejore los medios de vida, eleve la posición social o política de las poblaciones salvaguarde o restaure sitios de patrimonio cultural natural o el uso de prácticas culturalmente significativas, o produzca otros beneficios sociales, culturales y/o políticos para la población local. | J14: • Revise la lista de posibles beneficios sociales en la La tabla "Beneficios de la restauración" se encuentra en los materiales de apoyo para esta herramienta. Por ejemplo, las actividades de restauración pueden reportar beneficios de índole social, cultural o política, como una mayor visibilidad de los valores culturales, el reconocimiento de los conocimientos ecológicos tradicionales, la consecución de logros políticos, el aumento de las oportunidades recreativas o la mejora de la equidad de género. La restauración también puede ser una forma de que los gobiernos sean vistos como líderes en la escena mundial y cumplan los compromisos de los acuerdos internacionales (por ejemplo, CMNUCC, CNULD, CNUDB, REDD+, ODS). Además, la restauración puede ser beneficiosa para países o comunidades con una conexión cultural histórica con los bosques u otros ecosistemas (por ejemplo, tradiciones y folclore basados en los bosques, medios de vida y empleo basados en los ecosistemas). • Considere si los beneficios enumerados en la tabla se reconocen o se consideran en los planes, programas o actividades de restauración en el paisaje objetivo. • Siempre que sea posible, distinga entre los beneficios sociales a corto, mediano y largo plazo, incluidos los resultados esperados una vez que la restauración se haya implementado por completo. • Tome nota de qué personas o grupos probablemente recibirían estos beneficios. | K14: • Si la respuesta es “sí”, ¿cuáles son los beneficios sociales esperados? | L14: ·
C15: 3. La restauración genera beneficios ambientales | D15: • ¿Se espera que la restauración del área objetivo genere beneficios ambientales? | I15: Se espera que la restauración del área objetivo genere beneficios ambientales sustanciales y a largo plazo, incluida la conservación y recuperación de la biodiversidad, una mayor mitigación y adaptación al cambio climático, una menor degradación de la tierra y la desertificación, y la restauración de servicios ecosistémicos vitales como la regulación del agua, la fertilidad del suelo y el secuestro de carbono. Estas mejoras contribuirán a aumentar la resiliencia ecológica y los medios de vida sostenibles a lo largo del tiempo. | J15: Algunos ejemplos de beneficios ambientales incluyen una mayor biodiversidad, una mayor seguridad de las cuencas hidrográficas, una mayor mitigación y adaptación al cambio climático y una mayor fertilidad del suelo, entre otros. En los materiales de apoyo para este diagnóstico se proporciona una descripción más completa de los beneficios ambientales previstos. Tabla “Beneficios de la Restauración”. • Siempre que sea posible, distinga entre los beneficios ambientales a corto, mediano y largo plazo, incluidos los resultados esperados una vez que la restauración se haya implementado por completo. | K15: • Si la respuesta es “sí”, ¿cuáles son los beneficios ambientales esperados? | L15: ·
B16: b. Conscientización | C16: 4. Los beneficios de la restauración se comunican públicamente | D16: • ¿Se comunican los beneficios de restaurar el área objetivo a todas las partes interesadas, incluidos todos grupos poblacionales, y se diseñan canales de comunicación para llegar a estas diversas partes interesadas? | I16: Los beneficios de la restauración del área objetivo se han comunicado claramente a los gestores del territorio, los grupos vulnerables y otras partes interesadas. | J16: • La comunicación puede realizarse a través de diversos canales, incluidos artículos, prensa, redes sociales, radio y televisión, visitas de demostración, obras de teatro callejeras u otras vías dirigidas a las partes interesadas y los responsables de la toma de decisiones pertinentes. • La comunicación entre pares sobre los beneficios de la restauración puede ser un medio eficaz para generar conciencia y motivar la acción. • Considere si esta comunicación está organizada como parte de una estrategia más amplia de participación de las partes interesadas. • Una lista más completa de beneficios se incluye en los materiales de apoyo al diagnóstico en la tabla “Beneficios de la Restauración”. | K16: • ¿Qué beneficios podrían surgir? • ¿Cómo se ha dirigido o incluido específicamente la comunicación a las partes interesadas clave? | L16: ·
C17: 5. Se identifican oportunidades de restauración | D17: • ¿Se han identificado y cuantificado áreas objetivo o prioritarias para la restauración? | I17: Se han identificado y cuantificado áreas candidatas para la restauración. | J17: • Las áreas objetivo para la restauración son los lugares donde deben realizarse esfuerzos de restauración basándose en una combinación de consideraciones ambientales, sociales y económicas, incluyendo su contribución al clima global, la biodiversidad y otros objetivos ambientales. • La información sobre estas oportunidades puede presentarse en mapas nacionales o subnacionales y/o estrategias de restauración, y debe ser coherente con las áreas que las agencias gubernamentales utilizan al asignar fondos, programas y recursos de planificación para la restauración. • Considerar si las partes interesadas reconocen y hacen referencia a los mismos niveles de prioridad. | K17: • Si la respuesta es “sí”, ¿cuáles son las áreas candidatas? • Si la respuesta es “sí”, ¿qué tan grande es la oportunidad de restauración? | L17: ·
B18: c. Eventos de crisis | C18: 6. Los eventos de crisis se aprovechan | D18: • ¿Está experimentando la área objetivo un acontecimiento de crisis, o el riesgo de que se produzca en el futuro, que motivaría la restauración en el paisaje objetivo, y cómo podrían afectar esos acontecimientos a los diferentes grupos de población (rural y campesina, urbana, indígena, mujeres, jóvenes, etc.) y anticiparse a ellos? | I18: El gobierno y/o la sociedad civil utilizan el riesgo o la ocasión de eventos de crisis, incluso considerando escenarios futuros (incluido el climático), para generar apoyo político y público para la restauración de los ecosistemas. | J18: • Los eventos de crisis pueden incluir inundaciones, deslizamientos de tierra, sequías, incendios, tormentas de arena, escasez de madera, disminución del rendimiento de los cultivos, desempleo u otras perturbaciones que afectan a los ecosistemas y los medios de subsistencia. • Las crisis pueden crear oportunidades para catalizar la restauración (por ejemplo, generar impulso político después de un desastre), pero también pueden interrumpir, retrasar o detener los esfuerzos de restauración (por ejemplo, daños a la infraestructura, desvío de fondos, inestabilidad social). • Considere ambas dimensiones: (i) la capacidad de aprovechar las crisis para impulsar la restauración, y (ii) la resiliencia de los esfuerzos de restauración para resistir y recuperarse de las crisis. • Evaluar cómo los distintos grupos pueden verse afectados por los eventos de crisis y las respuestas de recuperación, incluidos los posibles impactos desproporcionados en las poblaciones vulnerables. • Considere si las prioridades de restauración están alineadas con los riesgos climáticos actuales y futuros, y si las inversiones se evalúan en función de su viabilidad climática a largo plazo (más allá de las decisiones de diseño técnico). • En el contexto del cambio climático, considérense tanto los acontecimientos pasados como los escenarios futuros, incluyendo el aumento de la frecuencia e intensidad de los choques climáticos. Herramientas como SPARCLE pueden utilizarse para visualizar rápidamente los impactos del cambio climático. • Cuando sea pertinente, identifique medidas para mitigar los riesgos para la implementación de la restauración (por ejemplo, planificación adaptativa, financiación diversificada, preparación de la comunidad). Aunque las crisis no son deseables, cuando ocurren pueden brindar oportunidades para movilizar el apoyo político y comunitario para la recuperación. | K18: • ¿Qué tipos de crisis han ocurrido en el panorama objetivo en el pasado? • ¿Qué tipos de crisis podrían ocurrir en el futuro? | L18: ·
B19: d. Requisitos legales | C19: 7. Existen leyes y políticas que exigen la restauración | D19: • ¿Existen leyes o políticas que obliguen a los propietarios o administradores de tierras a replantar o restaurar ecosistemas en áreas que han sido taladas (por ejemplo, bosques, pastizales, humedales)? | I19: El gobierno tiene leyes y políticas que requieren que los administradores de tierras permitan la recuperación de la vegetación natural o replantar árboles en ecosistemas naturales que hayan sido talados en el área objetivo. | J19: • Considerar si la legislación exige específicamente la restauración, como requisitos de reforestación, obligaciones de rehabilitar tierras o regulaciones de restauración de actividades extractivas. ¿Estas leyes y políticas especifican quién está obligado a restaurar, en qué situaciones y durante qué plazos? ¿Este marco legal se aplica a todos los límites del área objetivo? (Es decir, ¿los requisitos son de alcance nacional?) • Los requisitos de restauración suelen dirigirse más a las entidades involucradas en la tala comercial, la minería u otras actividades extractivas que a las actividades de subsistencia. | K19: • En caso afirmativo, ¿qué términos y condiciones específicos establece la ley (por ejemplo, qué restaurar, cuándo y cómo)? | L19: ·
C20: 8. Las leyes y políticas que exigen la restauración se comprenden y aplican ampliamente | D20: • ¿La ley o política que exige la restauración o rehabilitación del ecosistema se aplica de manera visible, creíble y justa, y es ampliamente comprendida por todos los actores relevantes, incluyendo a todos los grupos? | I20: Las leyes y políticas que exigen la restauración o rehabilitación de los ecosistemas (incluidas las actividades para recuperar las funciones de los ecosistemas, reducir la degradación o apoyar la regeneración natural) en el paisaje objetivo son comprendidas por los actores pertinentes y se aplican de manera visible, creíble y justa. | J20: • No basta con que exista una ley o política que exija la restauración o rehabilitación; es necesario que se aplique de manera justa, que las entidades afectadas la comprendan y que las autoridades la implementen para que sirva de motivación para la acción. • Considere si los requisitos legales para la restauración o rehabilitación del paisaje se comunican a las partes interesadas clave y se complementan con acciones como campañas de comunicación, medidas coercitivas (por ejemplo, multas) por infracciones y la garantía de recursos humanos y financieros adecuados para su cumplimiento. • Los mandatos gubernamentales de restauración o rehabilitación pueden generar susceptibilidad en torno a la participación del gobierno en decisiones sobre el uso de la tierra que, de otro modo, estarían bajo la jurisdicción de las comunidades tradicionales o los propietarios privados. Por lo tanto, la forma en que se comunican los requisitos legales y se complementan con otras políticas, incentivos y prácticas puede ser fundamental para su eficacia. | K20: • No basta con que exista una ley que exija la restauración; es necesario que las entidades afectadas la comprendan y las autoridades la apliquen para motivar la restauración. | L20: ·
B21: Condición habilitante | C21: Factor clave | D21: Pregunta | E21: Respuesta | F21: Nacional | G21: Regional | H21: Local | I21: Definición | J21: Orientación | K21: Pregunta(s) complementaria(s) | L21: Respuestas complementarias, justificación y documentos de soporte
A22: Habilitar | B22: e. Condiciones ecológicas | C22: 9. Las condiciones del suelo, el agua, el clima y fuego son adecuadas para la restauración. | D22: • ¿Son las condiciones de suelo, precipitaciones, temperatura, fuego y gestión del paisaje objetivo adecuadas para habilitar el crecimiento y la supervivencia de la vegetación plantada o en regeneración natural? | I22: Las condiciones de suelo, pluviosidad y temperatura del área objetivo son adecuadas para el rebrote de la vegetación natural, y el régimen de incendios no dificulta la recuperación de los ecosistemas naturales. | J22: • Este factor clave combina múltiples condiciones ecológicas que afectan la restauración del ecosistema. Cada condición (suelo, precipitaciones, temperatura, incendios) debe evaluarse por separado, pero la respuesta puede reflejar la suma de las cuatro. | K22: • Si la respuesta es “no”, ¿cuáles son las deficiencias en la idoneidad física? ¿Son viables los esfuerzos para superar estas limitaciones? | L22: ·
C23: 10. Se reducen al mínimo las plantas y animales que pueden obstaculizar la restauración | D23: • ¿Es posible eliminar o controlar eficazmente las plantas y los animales invasores no deseados que obstaculizan la recuperación del ecosistema en los sitios de restauración objetivo? | I23: Las especies invasoras persistentes en el área objetivo se pueden gestionar o controlar para evitar que interfieran con la vegetación replantada o en regeneración natural. Los sitios de restauración pueden protegerse del pastoreo del ganado que impide la recuperación del ecosistema. | J23: • Considerar si existen medidas de monitoreo o control (cercas, manejo de malezas, eliminación) para gestionar especies problemáticas o invasoras que puedan competir con o excluir a las especies utilizadas para la restauración. • Los paisajes pueden estar libres de plantas y/o animales no deseados ya sea porque nunca existieron de forma natural en el ecosistema o porque se han minimizado con éxito mediante la gestión. • Algunos ejemplos de especies que pueden obstaculizar los esfuerzos de restauración son Brachiaria spp. en Brasil, Imperata cylindrica en Indonesia, Pueraria montana (kudzu) en el sur de los Estados Unidos y animales de pastoreo no controlados (ganado vacuno, ovejas, cabras) en múltiples lugares. | K23: • Si la respuesta es “no”, ¿cuáles son las especies vegetales y/o animales persistentes y cómo afectan la restauración del ecosistema? | L23: ·
C24: 11. Semillas nativas, plántulas o poblaciones de origen están fácilmente disponibles | D24: • ¿El área objetivo tiene poblaciones fuente, bancos de propágulos del suelo (como sistemas de raíces subterráneas y bancos de semillas) o fuentes de bajo costo de semillas y plántulas nativas que puedan ser la base para la recuperación del ecosistema? | I24: El paisaje objetivo tiene fuentes naturales que apoyan la regeneración, como áreas naturales cercanas, rebrote de raíces subterráneas, semillas dispersadas por animales y fácil acceso a semillas y plántulas nativas de bajo costo que apoyan la recuperación del ecosistema. | J24: • Las poblaciones fuente viables o los bancos de propágulos del suelo de plantas nativas son de vital importancia para la restauración pasiva. • Este factor clave de éxito se aplica a toda la cadena de suministro de semillas y plántulas nativas, incluida la producción de semillas, la recolección y el procesamiento de semillas y los viveros de plántulas. | K24: • Si la respuesta es “no”, ¿dónde está la brecha (por ejemplo, semillas, recolectores de semillas, viveros, poblaciones fuente, bancos de propágulos del suelo)? | L24: ·
B25: f. Condiciones económicas | C25: 12. Gestión de otras actividades que se contraponen a la restauración. | D25: • ¿Están disminuyendo las presiones económicas derivadas de la producción agrícola, ganadera, de leña y/o de biocombustibles sobre las tierras degradadas y los ecosistemas naturales en la zona objetivo, y/o existen mecanismos para gestionar las demandas económicas contrapuestas sobre la tierra que impulsan la degradación de la misma? | I25: Las presiones económicas derivadas de la producción agrícola, ganadera, de leña y/o de biocombustibles sobre las tierras degradadas y los ecosistemas naturales en la zona objetivo están disminuyendo y/o se están gestionando activamente mediante políticas, incentivos, planificación del uso de la tierra o mejoras de la productividad, reduciendo así las presiones que impulsan la degradación de la tierra y "liberando" oportunidades para la restauración. | J25: • Las presiones sobre el uso del suelo que se contraponen a la restauración pueden provenir de la expansión agrícola, el desarrollo de infraestructuras, el pastoreo de ganado, la extracción de leña y la urbanización. • Considere si existen mecanismos para gestionar estas demandas que se contraponen a la restauración, como la planificación del uso del suelo, la zonificación, la intensificación agrícola en tierras existentes, las intervenciones en la cadena de suministro, los incentivos para la producción sostenible o las restricciones a la expansión en ecosistemas naturales. • Este factor clave de éxito es posiblemente uno de los más importantes a la luz de la creciente demanda mundial de tierras para producir cultivos, ganado y biocombustibles (Searchinger et al. 2013) • Este factor clave no se aplicaría cuando la tierra se restaura a sistemas agroforestales o silvopastoriles, que continúan produciendo cosechas y ganado, respectivamente. | K25: • ¿Cuáles son los principales usos alternativos de la tierra en competencia para las áreas candidatas a ser restauradas? | L25: ·
C26: 13. Existen cadenas de valor y/o mercados para productos básicos (madera, productos agrícolas) y productos ambientales (carbono, agua, biodiversidad) de áreas restauradas. | D26: • ¿Existen cadenas de valor, derechos sobre la tierra y políticas que permitan que los productos o servicios procedentes de tierras restauradas lleguen a los consumidores finales? | I26: En la medida en que la restauración forestal en el paisaje objetivo genere productos y servicios comercializables, se establecerán cadenas de valor que permitirán que estos productos lleguen desde el bosque restaurado hasta el consumidor final. | J26: • Este factor clave de éxito se refiere tanto al acceso al mercado como a la demanda del mercado de productos y servicios derivados de paisajes forestales restaurados. Una “cadena de valor” describe los múltiples pasos involucrados en la oferta de un producto o servicio, como la cosecha, la recolección, el procesamiento, el transporte y la distribución. Una cadena de valor derivada de la restauración sugiere que los individuos o grupos en el área objetivo pueden obtener medios de vida y actividades económicas locales como parte de la restauración de los ecosistemas. Además, las cadenas de valor de los productos ambientales incluyen la generación/suministro del servicio, la emisión de créditos de carbono o de naturaleza, la compra de créditos, etc. • Considerar si existen iniciativas, cooperativas o empresas en las áreas objetivo que vendan productos o servicios como resultado de las actividades de restauración. ¿Pueden los productores de estos lugares diferenciar sus productos y servicios a través de etiquetas, certificaciones o acceso a mercados preferenciales? ¿Existe infraestructura para procesar y agregar los productos y servicios ofrecidos desde los ecosistemas? ¿Existen promotores o desarrolladores de proyectos que apoyen la generación de créditos de carbono o de naturaleza? ¿Qué políticas que faciliten los mercados de carbono y naturaleza están en vigor? • Los servicios de los ecosistemas restaurados podrían incluir la recreación, el turismo y el suministro de agua. | K26: • Si la respuesta es “no”, ¿dónde están las brechas en esa cadena de valor? • Si la respuesta es “si”,¿cuál es la cadena de valor, incluidos los productores, intermediarios, consumidores finales, etc.? | L26: ·
B27: g. Condiciones de las políticas | C27: 14. Los usuarios de tierras, los propietarios de tierras o las comunidades tienen derechos de tenencia seguros sobre la tierra y los recursos naturales de la tierra. | D27: • ¿Quienes gestionan el área objetivo tienen derechos claros y seguros para utilizar la tierra, cosechar productos de forma sostenible y recibir los beneficios financieros que se derivarían de la restauración? ¿Estos derechos son accesibles a todas las partes interesadas, incluidas las mujeres y los grupos vulnerables? | I27: Las personas y comunidades que gestionan el área objetivo tienen derechos claros y seguros (por ejemplo, en forma de propiedad de la tierra o derechos de gestión de recursos naturales) sobre los beneficios que se derivarían de la restauración. | J27: • La falta (o inseguridad) de tenencia de la tierra y de derechos sobre los recursos naturales en el área objetivo puede desalentar la restauración que implica intervención humana. La gente no invertirá en plantar árboles y vegetación autóctona ni permitirá la regeneración natural en las tierras que gestiona si no es probable que se beneficie del estado restaurado. • Los derechos de tenencia y sobre los recursos naturales pueden adoptar la forma de propiedad privada de la tierra, tierras comunales, acuerdos consuetudinarios, certificados de derechos de uso, etc. • Considere también si la tenencia vigente se superpone o entra en conflicto con los derechos consuetudinarios. | K27: • Si la respuesta es “no”, ¿qué derechos faltan y para quiénes? | L27: ·
C28: 15. Se armonizan y racionalizan las políticas que afectan a la restauración | D28: • ¿Las políticas que podrían tener un impacto en la restauración del área objetivo están alineadas y optimizadas en un contexto global, nacional, subnacional y local? | I28: Las políticas públicas pertinentes están alineadas, son coherentes y optimizadas para apoyar eficazmente los esfuerzos de restauración en el área objetivo. Estas políticas se refuerzan mutuamente, minimizan las barreras administrativas innecesarias y crean un entorno propicio para su aplicación. Las políticas que promueven la igualdad de género y la inclusión social también se consideran esenciales para apoyar unos resultados de restauración inclusivos y sostenibles. | J28: • Las políticas nacionales sobre clima, biodiversidad y degradación de la tierra probablemente tendrán puntos de superposición para la restauración que pueden considerarse a través de los comités nacionales existentes. • Otras políticas a considerar incluyen aquellas sobre agricultura, industrias extractivas, agua, planificación del uso de la tierra, infraestructura y recursos naturales. • En algunos casos, las políticas de conservación de la naturaleza u otros sectores pueden inhibir la restauración (por ejemplo, leyes que prohíben la extracción de semillas nativas de áreas protegidas, leyes que prohíben la cosecha de especies de árboles nativos, subsidios que incentivan los factores de degradación). | K28: • Si la respuesta es “no”, ¿cuáles políticas no están alineadas o simplificadas? | L28: ·
C29: 16. Existen restricciones a la tala, degradación o perturbación de los ecosistemas naturales restantes (bosques, pastizales, humedales). | D29: • ¿El área objetivo tiene leyes que restringen la tala o desmonte de los ecosistemas naturales restantes? | I29: El área objetivo tiene leyes que restringen la limpieza o tala de los ecosistemas naturales restantes. | J29: • Las restricciones a la tala de los bosques y ecosistemas naturales restantes pueden impedir una mayor expansión de áreas degradadas o taladas. Estas restricciones también crean un incentivo para restaurar la productividad de áreas ya taladas, ya que se reducen las oportunidades de utilizar la frontera forestal. • Las restricciones también pueden adoptar la forma de una extensa red de parques nacionales y bosques nacionales, una extensa red de territorios indígenas forestados, normas de protección de ecosistemas en tierras comunales, normas de “cero pérdidas netas”, porcentajes específicos de tierra que se requiere que permanezca como bosque (por ejemplo, el Código Forestal de Brasil) y más. • Un componente importante de este factor clave de éxito es que los “bosques y ecosistemas naturales” hayan sido claramente definidos por la jurisdicción que patrocina la restricción (por ejemplo, el gobierno nacional). Esta definición debe incluir los bosques primarios, los bosques secundarios y los bosques degradados y otros ecosistemas con potencial de restauración. Nota: Los posibles efectos de desplazamiento o fugas (por ejemplo, el desplazamiento de la limpieza a otras áreas) se abordan en una sección aparte de esta evaluación y deben considerarse junto con esta pregunta. | K29: • Si es así, ¿cuáles son esas leyes? | L29: ·
C30: 17. Se aplican restricciones a la tala de los ecosistemas naturales restantes (por ejemplo, bosques, pastizales, humedales). | D30: • ¿Se aplican adecuadamente estas restricciones de limpieza o tala? | I30: Las leyes que restringen la tala de los ecosistemas naturales restantes se aplican adecuadamente. | J30: • No basta con que existan regulaciones que restrinjan la tala de los ecosistemas naturales restantes; es necesario que las autoridades pertinentes hagan cumplir las restricciones. • Particularmente en áreas remotas, la aplicación de la ley depende de la capacidad de las organizaciones encargadas de hacer cumplir la ley y de los incentivos que tienen para ejercer actividades de aplicación de la ley. | K30: • Si la respuesta es "no", ¿por qué no? | L30: ·
B31: h. Condiciones sociales y culturales | C31: 18. Las mujeres, los jóvenes y los pueblos indígenas participan en la toma de decisiones sobre restauración | D31: • ¿Las mujeres, los jóvenes y los pueblos indígenas que viven en el área objetivo y sus alrededores, junto con los sistemas culturales, las estructuras de gobernanza tradicionales y los sistemas de conocimiento que representan, participan de manera significativa en la toma de decisiones sobre restauración (por ejemplo, diseño de programas, establecimiento de objetivos, gestión, seguimiento y selección de indicadores)? | I31: Se reconoce y apoya explícitamente a las mujeres, los jóvenes y los pueblos indígenas como participantes clave en la planificación y ejecución de la restauración a todas las escalas. Sus sistemas culturales, estructuras de gobernanza tradicionales y conocimientos se respetan e integran en los órganos decisorios, los acuerdos de gobernanza y los procesos de supervisión, garantizando resultados de restauración inclusivos, representativos y culturalmente apropiados. | J31: • La toma de decisiones relacionadas con áreas (incluida la planificación, el diseño, la gestión y el seguimiento) debe ser inclusiva y culturalmente apropiada. Cuando la participación es limitada o extractiva, los esfuerzos de restauración corren el riesgo de fragmentación, debilitamiento de la apropiación local y distribución desigual de los beneficios, especialmente para las mujeres, los jóvenes y los pueblos indígenas. • Aprovechar y fortalecer las instituciones locales existentes y los procesos culturalmente arraigados (por ejemplo, cooperativas forestales a nivel de aldeas, grupos de mujeres, organizaciones de pueblos indígenas, asociaciones de jóvenes y sistemas de gobernanza tradicional) pueden respaldar los acuerdos de cogestión, mejorar la participación local y aumentar la adopción a largo plazo de iniciativas de restauración. • La planificación e implementación de la restauración deben reconocer y respetar los sistemas culturales en general (incluidos los valores, conocimientos y prácticas de diversos grupos de partes interesadas) e integrar estas perspectivas en los procesos de toma de decisiones, gestión y monitoreo. • Una participación eficaz e inclusiva requiere transparencia y rendición de cuentas en la toma de decisiones, respeto por el consentimiento libre, previo e informado (CLPI) cuando corresponda, y mecanismos de quejas y retroalimentación accesibles y confiables que permitan a las partes interesadas plantear sus inquietudes y posibilitar la corrección del curso cuando los procesos o resultados fallan. | K31: • Si la respuesta es "no", ¿qué grupos no están bien representados? • Si la respuesta es "no", ¿de qué aspectos de la restauración quedan excluidos los grupos vulnerables? | L31: ·
C32: 19. La población local se beneficia de la restauración | D32: • ¿Las personas que viven en el área objetivo y sus alrededores pueden capturar o disfrutar los beneficios generados por la restauración, como mejores medios de vida o servicios ecosistémicos? | I32: Las comunidades que viven en las zonas objetivo o en sus alrededores ven atendidas sus necesidades gracias a los esfuerzos de restauración y reciben beneficios medioambientales (por ejemplo, mejora de la calidad del agua, aumento del suministro de productos forestales) o económicos (por ejemplo, fuentes de ingresos alternativas, mejora de los medios de subsistencia) gracias a la restauración. | J32: • La documentación de planificación y el diseño técnico de cualquier iniciativa de restauración deben incluir marcos y mecanismos para garantizar que las personas que viven en las áreas restauradas o adyacentes a ellas sean los principales beneficiarios de los resultados positivos de la restauración. Aquí encontrará ejemplos de los beneficios que puede reportar la restauración. • Los planificadores o implementadores de restauraciones deben preguntarse continuamente: Entre los beneficios sociales, culturales, políticos, medioambientales y económicos identificados, ¿especifican los planes de restauración qué personas o grupos locales se espera que se beneficien de las actividades de restauración? ¿Se corresponden estos beneficios con las necesidades locales? ¿Los beneficios que recibe la población local son razonables, equitativos y confiables? • Si la población local no percibe los beneficios, tendrá pocos incentivos para cambiar sus comportamientos a fin de posibilitar la restauración o sostener el paisaje restaurado a largo plazo. | K32: • Si la respuesta es “no”, ¿qué barreras o limitaciones impiden que las comunidades locales accedan a los beneficios de la restauración? | L32: ·
B33: i. Condiciones institucionales | C33: 20. Los roles y responsabilidades para la restauración están claramente definidos | D33: ¿Están claramente definidos los roles y responsabilidades para la restauración del ecosistema en el área objetivo, son comprendidos por los actores relevantes y acompañados por la autoridad y, cuando es necesario, existen mecanismos de resolución de conflictos? | I33: Los roles y responsabilidades para la restauración en el área objetivo están claramente definidos, son comprendidos entre los actores relevantes (por ejemplo, el gobierno, la sociedad civil, el sector privado y otras partes interesadas pertinentes) y están acompañados por la autoridad. Y existen y se aplican mecanismos de resolución de conflictos | J33: • Considere si existen agencias, instituciones o grupos designados con el poder de implementar la restauración del ecosistema. • En ausencia de claridad sobre los roles y responsabilidades, puede producirse inacción debido a que no se cubren roles importantes, a incertidumbre sobre quién hace qué o a que instituciones y grupos reclaman responsabilidades y derechos superpuestos. • Para responder adecuadamente a esta pregunta, los usuarios tal vez necesiten trazar un mapa de los mandatos existentes para la planificación, coordinación, implementación y monitoreo de la restauración entre entidades públicas, grupos y organizaciones privadas, propietarios de tierras, usuarios de tierras y otras partes interesadas clave. Los roles, responsabilidades y derechos también pueden definirse en leyes, políticas o prácticas consuetudinarias. • Los mecanismos de resolución de conflictos para la restauración de ecosistemas son sistemas estructurados y colaborativos diseñados para gestionar disputas entre las partes interesadas con respecto a la gestión, el acceso y el uso de los recursos naturales u otras actividades durante los proyectos de restauración. | K33: • Si la respuesta es “no”, ¿qué falta en términos de claridad de roles y responsabilidades? | L33: ·
C34: 21. Se mantiene una coordinación institucional eficaz | D34: ¿Se coordinan eficazmente las partes interesadas pertinentes del gobierno, la sociedad civil y el sector privado -por ejemplo, a través de un grupo de trabajo o un proceso multilateral- para diseñar, aplicar y supervisar la restauración del ecosistema en el área candidata, garantizando al mismo tiempo que estos esfuerzos incluyan a los grupos vulnerables? | I34: Los actores relevantes del gobierno, la sociedad civil y/o el sector privado están suficientemente coordinados para diseñar, implementar y supervisar la restauración en el área objetivo. | J34: • Considere si las instituciones públicas y privadas se han comprometido a establecer un liderazgo y mandatos claros para la restauración. ¿Existe una acción conjunta demostrada en forma de mecanismos de coordinación, comités, grupos de trabajo o alianzas que se reúnan periódicamente y tomen decisiones sobre la restauración? ¿Estos esfuerzos de coordinación incluyen planes, datos, aportes técnicos y seguimiento compartidos, especialmente entre los niveles de gobernanza local, regional y nacional? | K34: • Si la respuesta es “no”, ¿qué falta en términos de coordinación? | L34: ·
B35: Condición habilitante | C35: Factor clave | D35: Pregunta | E35: Respuesta | F35: Nacional | G35: Regional | H35: Local | I35: Definición | J35: Orientación | K35: Pregunta(s) complementaria(s) | L35: Respuestas complementarias, justificación y documentos de soporte
A36: Implementar | B36: j. Liderazgo | C36: 22. Existen lideres nacionales y/o locales de restauración | D36: • ¿Existe un defensor carismático y comprometido de la restauración para el área objetivo? ¿Representan a todas las partes interesadas de la sociedad, incluidas las mujeres, los jóvenes y los pueblos indígenas? | I36: Existen personas carismáticas (o instituciones poderosas) que pueden inspirar eficazmente a los responsables de la toma de decisiones para perseguir la restauración, movilizar apoyos y mantener el impulso a lo largo del tiempo en el área candidata | J36: • Los lideres locales de la restauración pueden ser personas o grupos comprometidos con la restauración del área y capaces de actuar en consecuencia. En algunos paisajes o ecosistemas, puede ser necesario resaltar a los lideres de restauracion y darles un perfil visible. • Históricamente, los ejemplos exitosos de restauración contaron con un promotor o un fuerte apoyo gubernamental. Pocos carecían de ambos. | K36: • ¿Quién es el lider local de la restauración(es)?
C37: 23. Existe un compromiso político sostenido | D37: • ¿Existe un compromiso claro y sostenido a largo plazo por parte de las instituciones gubernamentales y no gubernamentales para apoyar los esfuerzos de restauración en el área objetivo, incluidos los presupuestos asignados? | I37: El compromiso de las autoridades gubernamentales (en los niveles pertinentes, cuando corresponda) y de las instituciones no gubernamentales con la restauración en el área objetivo está claramente establecido y reconocido como un compromiso sostenido y de largo plazo y con un presupuesto asignado. | J37: • Puede ser difícil predecir el compromiso a largo plazo de un gobierno u organización. En tales situaciones, hay que considerar si el compromiso trasciende a los partidos políticos y si la restauración producirá beneficios recurrentes para las principales partes interesadas. • Los objetivos de restauración del gobierno podrían ser apoyados con fondos públicos específicos. A la hora de revisar, compruebe si los objetivos llevan aparejado un presupuesto o mecanismo de financiación claro, que indique una demanda real y sostenida, o si existe un plan de financiación. | K37: • En caso afirmativo, ¿cuál es la prueba del compromiso expreso y de quién?
B38: k. Conocimiento | C38: 24. Existen "conocimientos técnicos" de restauración pertinentes para el área candidata | D38: • ¿Existe conocimiento local diverso (incluido el conocimiento indígena, el conocimiento ecológico tradicional y el conocimiento con perspectiva de género) sobre cómo implementar la restauración a escala en el área objetivo? | I38: Los expertos locales conocen las técnicas de restauración (por ejemplo, regeneración natural y asistida, conocimientos tradicionales) adaptadas al área candidata, o generan investigaciones al respecto. | J38: • La experiencia local puede provenir del conocimiento tradicional de las comunidades que viven en el paisaje o sus alrededores, de expertos de universidades y servicios de extensión rural, y de organizaciones no gubernamentales activas en ese campo. • El conocimiento puede generarse localmente o importarse de otro lugar, pero debe ser comunicado o impartido por profesionales locales. Se puede obtener orientación sobre “mejores prácticas” en materia de restauración de parte de universidades, organizaciones no gubernamentales o agencias de extensión, así como también de individuos o grupos locales con experiencia en restauración a largo plazo. | K38: • Si la respuesta es “no”, ¿cuáles son las lagunas de conocimiento más importantes?
C39: 25. El "saber hacer" de la restauración se transfiere a través de homólogos o servicios de extensión | D39: • ¿Existen servicios de extensión, visitas de agricultor a agricultor, grupos de mujeres, redes locales y/u otros medios de concientización y desarrollo de capacidades para la restauración, y cuentan con los recursos adecuados en el área objetivo o a nivel nacional? | I39: Se cuenta con asistencia técnica y extensión rural (“servicios de extensión”), visitas de agricultor a agricultor, grupos de mujeres, redes locales y/u otros medios de concientización y desarrollo de capacidades para la restauración, y se cuenta con los recursos adecuados en el área candidata. | J39: • El intercambio de conocimientos puede documentarse en servicios de extensión formales, como visitas de campo, programas de capacitación, escuelas de campo, materiales impresos y sitios de demostración. • Considerar si los grupos de aprendizaje informales sobre restauración están compartiendo información o coordinando actividades, incluidos grupos de mujeres, asociaciones de productores o intercambio de conocimientos entre pueblos indígenas. Esta comunicación de "agricultor a agricultor" o de "gestor de tierras a gestor de tierras" puede ser uno de los medios más eficaces de educación y formación. • Las redes o asociaciones locales para el desarrollo de capacidades en materia de restauración de ecosistemas, agroforestería o reforestación pueden ser mencionadas en documentos o informes nacionales de organizaciones no gubernamentales. | K39: • Para el panorama candidato, ¿qué entidades están mejor posicionadas para prestar servicios de extensión?
B40: l. Diseño técnico | C40: 26. El diseño de la restauración tiene una base técnica y adaptada al cambio climático | D40: • ¿El plan de restauración del área objetivo se basa en las mejores prácticas, incorporando la mejor ciencia disponible, el conocimiento ecológico tradicional y enfoques resilientes al clima? | I40: El plan de restauración se basa en las mejores prácticas de diseño, ejecución y mantenimiento de las actividades de restauración. El plan de restauración del paisaje incorpora la mejor ciencia disponible y enfoques resilientes al clima que garantizan que la intervención, incluidos aspectos como la selección de especies y las técnicas de restauración, sea apropiada para el contexto local y los objetivos de la intervención, y reduzca la vulnerabilidad de la intervención de restauración a los impactos climáticos como sequías, inundaciones, incendios forestales y temperaturas extremas. | J40: • Considerar si los enfoques para la restauración de los ecosistemas están respaldados por la investigación científica, el conocimiento local o las prácticas indígenas para recuperar los ecosistemas naturales y reducir la vulnerabilidad a los impactos climáticos. • El diseño técnico debe abordar aspectos tales como la preparación del sitio, la pendiente, la selección de especies, el espaciamiento de los árboles y el mantenimiento, o cómo eliminar las presiones que impiden que la vegetación natural vuelva a crecer (por ejemplo, el ganado, los incendios). • Los planes de restauración deben tener en cuenta los impactos climáticos proyectados para ser resilientes al clima. | K40: • Si la respuesta es “no”, ¿qué falta en el plan?
