Workbook

Sheet Instruções
A1: Diagnóstico de restauração
A2: Versão 2.0 - Atualizado em 2026
B4: Informações gerais | H4: Como funciona o diagnóstico? | N4: Outras considerações
B5: Bem-vindo ao diagnóstico de restauração da WRI! Uma ferramenta de avaliação rápida para avaliar o grau de preparação de uma área geográfica ou escala para a restauração e definir ações estratégicas que garantam o sucesso a longo prazo. Uma ferramenta independente desenvolvida como parte do ROAM (Metodologia de Avaliação de Oportunidades de Restauração) https://iucn.org/resources/grey-literature/guide-restoration-opportunities-assessment-methodology-roam | H5: O diagnóstico segue um processo de três passos. Recomenda-se vivamente que leia a seção anterior antes de começar. Além disso, sugere-se uma etapa preparatória. Consulte a planilha «Antes de começar». Cada etapa corresponde a uma seção da ferramenta, e cada uma delas é explicada em uma aba separada deste documento: Passo 1. Definir o escopo; Passo 2. Avaliar os fatores-chave para a restauração; Passo 3. Propor estratégias para corrigir as deficiências A planilha «Tabela resumida» gera uma tabela de resumo com base nos dados inseridos nas etapas 1, 2 e 3. | N5: Cronograma sugerido para a realização do diagnóstico Passo 1. Definir o escopo 2 a 3 dias Passo 2. Avaliar os fatores-chave para a restauração 2 a 4 semanas Passo 3. Selecionar medidas para corrigir as deficiências. 2 a 3 semanas O cronograma sugerido fornece uma estimativa aproximada do tempo necessário para realizar o diagnóstico. A duração real pode variar de acordo com o contexto, o escopo da avaliação, a disponibilidade de informações, os processos de participação das partes interessadas e o tempo alocado pela equipe de execução. Em alguns casos, os passos podem se prolongar se for necessário realizar consultas adicionais, coletar dados ou realizar processos de validação. Por outro lado, o processo pode avançar mais rapidamente quando as informações e as partes interessadas estão facilmente disponíveis.
B10: O que é a ferramenta de diagnóstico de restauração? O Diagnóstico de Restauração ajuda a avaliar se existem os fatores-chave culturais, financeiros, políticos, institucionais e ecológicos necessários para que a restauração dos ecossistemas seja bem-sucedida. Ao identificar as lacunas e os desafios, você poderá passar de um planejamento geral para uma ação específica e eficaz.
B14: Por que essa ferramenta é útil? Um diagnóstico ajuda a identificar os principais fatores que influenciam o sucesso da restauração e permite planejar e agir de forma mais estratégica.
B17: Será que sou a pessoa certa para usar essa ferramenta? Você deve utilizar esta ferramenta se for responsável pelo planejamento ou coordenação de políticas, ações e medidas de restauração em nível nacional ou regional e desejar conhecer as condições atuais necessárias para realizar uma restauração bem-sucedida.
N19: Qual é o resultado final desse diagnóstico? O diagnóstico permite chegar a um consenso sobre os fatores-chave que influenciam o sucesso da restauração e estabelecer um conjunto de medidas priorizadas para reforçar esses fatores e viabilizar a restauração na área ou na escala previstas.
H21: A coluna «Orientação adicional» fornece mais detalhes sobre cada fator-chave para orientar suas respostas no passo 2.
B22: Nota sobre a participação: Embora uma única pessoa possa se encarregar da inserção de dados, a ferramenta se mostra mais eficaz quando utilizada de forma participativa, reunindo as perspectivas de diversas partes interessadas e especialistas.
B27: Quais são os fatores-chave? Os fatores-chave são as condições e os elementos que influenciam o sucesso e a sustentabilidade a longo prazo das iniciativas de restauração. Por exemplo, entre esses fatores estão os benefícios proporcionados pela restauração, os conhecimentos disponíveis sobre a restauração, as condições do mercado e as políticas relacionadas à restauração, entre outros. A título de referência, a etapa 2 inclui uma lista completa das condições favoráveis e dos fatores-chave.
N29: Documentos a serem reunidos antecipadamente (lista não exaustiva) +Planos, estratégias ou programas nacionais de restauração +Compromissos de restauração no âmbito da CDB e da CMNUCC +Leis ou políticas relacionadas à restauração florestal, agrícola ou de outros ecossistemas pertinentes +Documentação subnacional das ações de restauração +Planos de desenvolvimento municipal nas paisagens-alvo
H30: Se precisar de mais informações sobre como esta ferramenta foi desenvolvida, você pode consultar uma explicação detalhada por escrito do diagnóstico on-line em: XXXX
B35: Utilização dos dados: Seus dados serão utilizados de acordo com a Política de Privacidade da WRI, que pode ser consultada no link a seguir: https://www.wri.org/about/privacy-policy. Gostaríamos de destacar que você pode interagir com a WRI online por meio de diversos sites, aplicativos, ferramentas de diagnóstico, ferramentas digitais, pesquisas, e-mails, páginas nas redes sociais e outros serviços online através dos quais realizamos pesquisas, atividades programáticas, comunicações ou iniciativas de participação (em conjunto, os «Serviços»).

Sheet Antes de começar
B1: Antes de começar
B3: Antes de começar
B4: Por que concluir esta fase? Essa fase de preparação contribui para garantir que o diagnóstico seja realizado sem contratempos e produza resultados nos quais as partes interessadas possam confiar e com base nos quais possam agir. Isso ajuda a garantir: Escalação: As funções e responsabilidades estão bem definidas. Inclusão: Contam-se com a participação das partes interessadas relevantes. Eficiência: As informações e os documentos essenciais já estão prontos.
B6: Como concluir esta fase
B7: 1. Nomear um responsável pelo processo Designar uma pessoa encarregada de coordenar o diagnóstico e de compilar os resultados. 2. Definir a participação das partes interessadas Escolha como as partes interessadas contribuirão: Workshops para debates em grupo e troca rápida de ideias Entrevistas sobre temas específicos Contribuições à distância de especialistas técnicos que colaboram remotamente 3. Reunir materiais essenciais Reunir documentos e dados relevantes que fundamentem a avaliação
B9: Planejamento da participação das partes interessadas
B10: Comece analisando o panorama social em torno do setor de restauração: quem são os usuários, quem é afetado e quem exerce influência. Identificar as necessidades, as motivações e as relações das partes interessadas para compreender onde podem surgir atritos ou pontos de convergência. Aproveite essas informações para criar pontos de contato — workshops, entrevistas, processos de feedback — que sejam inclusivos, iterativos e se adaptem ao contexto. Trate as partes interessadas como co-criadores, e não apenas como fontes de dados, para melhorar a facilidade de uso, a relevância e a aceitação da ferramenta. Ferramenta recomendada para mapear os cenários sociais: https://www.wri.org/research/mapping-social-landscapes-guide-identifying-networks-priorities-and-values-restoration
B17: Documentos que se recomenda reunir (lista não exaustiva)
B18: □ A. Contexto normativo e jurídico [ ] Estratégias ou programas nacionais de restauração. [ ] Leis e regulamentos (silvicultura, agricultura, ordenamento do território, recursos hídricos). [ ] Compromissos internacionais (CMNUCC, CDB, CNULD). [ ] Planos nacionais de desenvolvimento e contribuições determinadas a nível nacional (NDC). □ B. Execução e planejamento [ ] Planos de ação para restauração em nível subnacional ou regional. [ ] Planos de desenvolvimento municipal para as paisagens em questão. [ ] Documentação de programas financiados por doadores. [ ] Orçamentos institucionais e organogramas existentes. □ C. Dados biofísicos e socioeconômicos [ ] Avaliações da cobertura do solo e da degradação do solo. [ ] Mapas de oportunidades de restauração (por exemplo, resultados do ROAM). [ ] Dados socioeconômicos (situação de posse da terra, dependência dos meios de subsistência, análise de mercado). □ D. Monitoramento e valores de referência [ ] Dados provenientes de sistemas de monitoramento da paisagem (por exemplo, Global Forest Watch). [ ] Indicadores de restauração existentes e relatórios históricos de progresso.
B20: Garantir a inclusão e a equidade
B21: É possível que alguns participantes se mostrem relutantes em participar das discussões em grupo, e as dinâmicas sociais e de gênero locais podem excluir certos grupos. A equipe coordenadora deve adaptar os métodos de participação para garantir que as diversas perspectivas sejam levadas em conta. Isso pode ser feito da seguinte maneira: • organizar grupos de discussão separados para mulheres e/ou comunidades indígenas • utilizar as línguas locais • contar com a participação de intermediários de confiança • oferecer ajuda para o deslocamento ou uma compensação financeira quando necessário • estabelecer acordos para garantir um espaço seguro • permitir a participação anônima por escrito no caso de perguntas delicadas

Sheet Passo 1. Definir o escopo
B1: Passo 1. Definir o escopo
B3: Por que esta etapa é importante?
B4: Nesta etapa, você pode dedicar algum tempo para definir claramente o escopo da avaliação. Isso inclui decidir onde será realizado o diagnóstico, o prazo previsto e os objetivos da restauração da paisagem. Tomar essas decisões desde o início ajuda a garantir que o diagnóstico se concentre nos aspectos, nas partes interessadas e nas oportunidades de recuperação adequadas.
B7: Selecione a região geográfica e os tipos de ecossistema
B8: Defina o contexto geográfico, a escala ou a paisagem em que o diagnóstico será realizado. É importante selecionar a área geográfica adequada, pois ela determina quais ecossistemas serão avaliados, quais partes interessadas devem participar e quais opções de restauração são pertinentes. Isso pode incluir: Nacional Subnacional (ou seja, município, estados, distrito) Paisagem (ou paisagem marinha, se for o caso) Área de restauração Transfronteiriço (ou seja, dois ou mais países)
B14: Tipos de ecossistemas de captura
B15: A lista de ecossistemas a seguir é meramente orientativa.
B16: Referência: Tipologia Global de Ecossistemas da IUCN 2.0
B17: https://portals.iucn.org/library/sites/library/files/documents/2020-037-En.pdf, https://global-ecosystems.org/
B18: Terrestre | F18: Água doce | I18: Marinho
B19: Florestas tropicais e subtropicais | F19: Turfeiras | I19: Plataformas marítimas
B20: Florestas e áreas arborizadas temperadas e boreais | F20: Zonas úmidas | I20: Manguezais e sistemas costeiros
B21: Matagais e bosques arbustivos | F21: Ecossistemas ribeirinhos | I21: Fundo do mar profundo
B22: Savanas e pradarias | F22: Bacias hidrográficas
B23: Desertos e semidesertos | F23: Águas doces artificiais
B24: Polar-alpino
B25: Sistemas produtivos e agrícolas
B26: Paisagens urbanas
B28: Definir o horizonte temporal
B29: Decida até que ponto se prevê que o projeto de restauração chegue no futuro. A restauração é um processo de longo prazo. Embora alguns benefícios possam surgir rapidamente, muitos resultados ecológicos e sociais levam anos para se concretizar. Estabelecer um prazo claro ajuda a definir expectativas realistas e garante que as iniciativas de restauração estejam em conformidade com as políticas e os ciclos de planejamento existentes. Aposte em uma visão de longo prazo, mesmo que as medidas sejam implementadas no curto prazo. Sempre que possível, o cronograma deve ser adaptado aos planos nacionais ou regionais.
B31: Definir os objetivos de restauração
B32: Explique o que você pretende alcançar com a restauração da paisagem. Os objetivos de restauração podem se concentrar em um único ecossistema (como florestas ou manguezais) ou em uma combinação de ecossistemas e usos do solo, incluindo sistemas agrícolas ou agroflorestais. Os objetivos podem ser descritos tanto antes quanto depois da realização do diagnóstico, dependendo do contexto e da forma como esse diagnóstico é conduzido. Entre os objetivos habituais da restauração estão (lista não exaustiva): - Conservação da biodiversidade - Mitigação ou adaptação às mudanças climáticas - Melhoria dos meios de subsistência - Segurança hídrica - Produção de alimentos Objetivos claramente definidos ajudam a determinar quais opções de restauração serão consideradas e facilitam o consenso entre as partes interessadas sobre como o sucesso será definido.
B34: Validar o escopo com as partes interessadas
B35: Antes de prosseguir, confirme o escopo com as partes interessadas relevantes. Uma validação precoce contribui para gerar confiança, um entendimento comum e um sentimento de envolvimento no processo de diagnóstico. Além disso, contribui para garantir que a avaliação reflita as prioridades e realidades locais.

Sheet Passo 2. Avaliar os fatores
A1: Passo 2. Avalie os fatores-chave para a restauração, selecionando uma resposta para cada uma das perguntas a seguir. É apresentada uma definição e uma série de perguntas complementares para obter mais informações.
B3: Objetivo Na etapa 2, avalia-se se os fatores-chave para o sucesso da restauração dos ecossistemas estão atualmente: • Em funcionamento • Parcialmente em funcionamento • Fora de funcionamento O objetivo não é realizar uma análise exaustiva de cada aspecto do processo de restauração, mas identificar rapidamente os pontos fortes, os pontos fracos e os possíveis obstáculos para uma restauração bem-sucedida. Estrutura da avaliação A avaliação está organizada em torno de três temas gerais: 1. Motivar: fatores que inspiram ou motivam para impulsionar processos que conduzem à restauração 2. Facilitar: fatores que criam um contexto favorável para a restauração 3. Implementar: fatores relacionados às capacidades e aos recursos necessários para impulsionar a implementação das medidas de restauração no terreno | K3: O código de cores significa o seguinte:
K4: Verde = EM FUNCIONAMENTO
K5: Amarelo = PARCIALMENTE EM FUNCIONAMENTO
K6: Vermelho = FORA DE FUNCIONAMENTO
K7: Branco: NÃO APLICÁVEL
B12: Condição habilitante | C12: Fator-chave | D12: Pergunta | E12: Resposta | F12: Nacional | G12: Regional | H12: Local | I12: Definição | J12: Orientação | K12: Pergunta(s) complementar(es) | L12: Respostas complementares, justificativa e documentos comprovativos
A13: Motivar | B13: a. Benefícios | C13: 1. A restauração gera benefícios econômicos. | D13: • A restauração da área-alvo deverá gerar benefícios econômicos que resultem em um impacto financeiro ou econômico líquido positivo em toda a economia, em comparação com o uso atual da terra? | I13: • A restauração da área-alvo deverá gerar benefícios econômicos que resultem em um impacto financeiro ou econômico líquido positivo em toda a economia, em comparação com o uso atual da terra? | J13: Espera-se que a restauração da área candidata produza benefícios econômicos (por exemplo, diversificação econômica, prevenção de danos, novos produtos comercializáveis) que criem um impacto financeiro líquido positivo (benefícios privados) e/ou um impacto líquido positivo em toda a economia (benefícios públicos) em relação ao uso atual da terra. Nota lateral: “Impactos econômicos que se referem a benefícios ambientais que funcionam como bens públicos, ou a impactos econômicos em toda a economia que capturam os efeitos indiretos relacionados à restauração nas cadeias de valor e na economia em geral, incluindo o crescimento do PIB e o emprego. Esses impactos geralmente decorrem de benefícios econômicos, como diversificação, prevenção de danos e novos produtos de mercado possibilitados pela restauração. | K13: • Os benefícios econômicos da restauração correspondem aos resultados positivos gerais em termos de renda ou finanças que resultam da implementação de atividades de restauração em comparação com um cenário de manutenção do status quo. • Alguns exemplos de benefícios econômicos incluem aumento da renda, melhores oportunidades de negócios, aumento da produção de produtos essenciais ou novas oportunidades de emprego resultantes dos esforços de restauração. Uma lista mais completa dos potenciais benefícios está incluída nesta ferramenta na tabela “Benefícios da Restauração”. • O cronograma para esta resposta deve levar em consideração o plano de atividades de restauração, reconhecendo que os processos de restauração e seus benefícios ocorrem a longo prazo. •Sempre que for possível, distinga entre os benefícios de curto, médio e longo prazo, incluindo os resultados esperados assim que a restauração tenha sido completamente implementada. • Anote quais pessoas ou grupos têm maior probabilidade de receber esses benefícios. • Alguns proprietários de terras podem temer que a “restauração” signifique a perda de suas terras, seus direitos de uso ou sua renda em relação ao status quo. Portanto, a resposta a esta pergunta pode ser comprovada por documentos que demonstrem como os benefícios líquidos superam os custos. Nota: A formalização dos direitos territoriais poderá surgir como um benefício adicional do projeto de restauração. Em alguns casos, a implementação do projeto e o desembolso de fundos para apoiar as atividades de restauração podem exigir que os direitos de propriedade da terra sejam claramente definidos. Consequentemente, isso poderia acelerar os processos de demarcação e permitir que as comunidades locais obtivessem títulos legais de suas terras.
C14: 2. A restauração gera benefícios sociais. | D14: • A restauração da área-alvo deverá gerar benefícios sociais, culturais ou políticos para as pessoas que vivem nessa área, incluindo grupos vulneráveis como mulheres, jovens e povos indígenas? | I14: • A restauração da área-alvo deverá gerar benefícios sociais, culturais ou políticos para as pessoas que vivem nessa área, incluindo grupos vulneráveis como mulheres, jovens e povos indígenas? | J14: Espera-se que a restauração da área-alvo melhore os meios de subsistência, eleve o status social ou político de populações vulneráveis, proteja ou restaure sítios de patrimônio cultural natural ou o uso de práticas culturalmente significativas, ou produza outros benefícios sociais, culturais e/ou políticos para a população local. | K14: • Revise a lista de possíveis benefícios sociais na tabela "Benefícios da Restauração" disponível nos materiais de apoio desta ferramenta. Por exemplo, as atividades de restauração podem gerar benefícios sociais, culturais ou políticos, como maior visibilidade dos valores culturais, reconhecimento dos conhecimentos ecológicos tradicionais, alcançar conquistas políticas, aumento das oportunidades de lazer ou melhoria da equidade de gênero. A restauração também pode permitir que os governos sejam vistos como líderes na esfera global e cumpram os compromissos assumidos em acordos internacionais (por exemplo, UNFCCC, UNCCD, UNCDB, REDD, ODS). Além disso, a restauração pode ser benéfica para países ou comunidades com uma ligação cultural histórica às florestas ou outros ecossistemas (por exemplo, tradições e folclore ligados à floresta, meios de subsistência e emprego baseados em ecossistemas). • Analise se os benefícios listados na tabela são reconhecidos ou considerados nos planos, programas ou atividades de restauração na paisagem em questão. •Sempre que for possível, distinga entre os benefícios sociais de curto, médio e longo prazo, incluindo os resultados esperados assim que a restauração tenha sido completamente implementada. • Anote quais pessoas ou grupos têm maior probabilidade de receber esses benefícios. | L14: ·
C15: 3. A restauração gera benefícios ambientais. | D15: • A restauração da área-alvo deverá gerar benefícios ambientais? | I15: • A restauração da área-alvo deverá gerar benefícios ambientais? | J15: Espera-se que a restauração da área-alvo gere benefícios ambientais substanciais e de longo prazo, incluindo a conservação e recuperação da biodiversidade, maior mitigação e adaptação às mudanças climáticas, menor degradação do solo e desertificação, e a restauração de serviços ecossistêmicos vitais, como regulação da água, fertilidade do solo e sequestro de carbono. Essas melhorias contribuirão para aumentar a resiliência ecológica e os meios de subsistência sustentáveis ao longo do tempo. | K15: •Alguns exemplos de benefícios ambientais incluem o aumento da biodiversidade, maior segurança das bacias hidrográficas, maior mitigação e adaptação às mudanças climáticas e aumento da fertilidade do solo, entre outros. Uma descrição mais completa dos benefícios ambientais previstos é fornecida nos materiais de apoio a este diagnóstico. Tabela “Benefícios da Restauração”. •Sempre que possível, distinga entre os benefícios ambientais de curto, médio e longo prazo, incluindo os resultados esperados assim que a restauração tenha sido completamente implementada. | L15: ·
B16: b. Conscientização | C16: 4. Os benefícios da restauração são comunicados publicamente. | D16: • Os benefícios da restauração da área-alvo são comunicados a todas as partes interessadas, incluindo os grupos vulneráveis, e os canais de comunicação são projetados para alcançar essas diversas partes interessadas?? | I16: • Os benefícios da restauração da área-alvo são comunicados a todas as partes interessadas, incluindo os grupos vulneráveis, e os canais de comunicação são projetados para alcançar essas diversas partes interessadas?? | J16: Os benefícios da restauração da paisagem alvo foram claramente comunicados aos administradores de terras, grupos vulneráveis e outras partes interessadas. | K16: • A comunicação pode ser realizada por meio de diversos canais, incluindo artigos, imprensa, redes sociais, rádio e televisão, visitas de demonstração, obras de teatro de rua ou outras vias direcionadas às partes interessadas e aos tomadores de decisão relevantes. • A comunicação entre pares sobre os benefícios da restauração pode ser um meio eficaz de aumentar a conscientização e motivar a ação. • Analise se esta comunicação está organizada como parte de uma estratégia mais ampla de envolvimento das partes interessadas. • Uma lista mais completa dos benefícios está incluída nos materiais de apoio ao diagnóstico, na tabela “Benefícios da Restauração”. | L16: ·
C17: 5. As oportunidades de restauração são identificadas. | D17: • As áreas prioritárias ou alvo para restauração foram identificadas e quantificadas? | I17: • As áreas prioritárias ou alvo para restauração foram identificadas e quantificadas? | J17: Foram identificadas e quantificadas as áreas adequadas para restauração | K17: • As áreas-alvo para restauração são os locais onde os esforços de restauração devem ser realizados com base em uma combinação de considerações ambientais, sociais e econômicas, incluindo sua contribuição para o clima global, a biodiversidade e outros objetivos ambientais. • As informações sobre essas oportunidades podem ser apresentadas em mapas nacionais ou subnacionais e/ou estratégias de restauração, e devem ser consistentes com as áreas que as agências governamentais utilizam ao alocar fundos, programas e recursos de planejamento para a restauração. • Analise se as partes interessadas reconhecem e se referem aos mesmos níveis de prioridade. | L17: ·
B18: c. Eventos de crisis | C18: 6. Eventos de crise são aproveitados | D18: • A área em questão está passando por um evento de crise, ou corre o risco de que um evento desse tipo ocorra no futuro, o que motivaria a restauração da paisagem em questão? E como esses eventos poderiam afetar diferentes grupos populacionais (rurais e camponeses, urbanos, indígenas, mulheres, jovens, etc.)? | I18: • A área em questão está passando por um evento de crise, ou corre o risco de que um evento desse tipo ocorra no futuro, o que motivaria a restauração da paisagem em questão? E como esses eventos poderiam afetar diferentes grupos populacionais (rurais e camponeses, urbanos, indígenas, mulheres, jovens, etc.)? | J18: O governo e/ou a sociedade civil aproveitam o risco ou a oportunidade de eventos de crise para gerar apoio político e público à restauração de ecossistemas. | K18: • Os eventos de crise podem incluir enchentes, deslizamentos de terra, secas, incêndios, tempestades de areia, escassez de lenha, diminuição do rendimento das culturas, desemprego ou outras perturbações que afetam os ecossistemas e os meios de subsistência. •As crises podem criar oportunidades para catalisar a restauração (por exemplo, gerar impulso político após um desastre), mas também podem interromper, retardar ou deter os esforços de restauração (por exemplo, danos à infraestrutura, desvio de recursos, instabilidade social). •Considere ambas as dimensões: (i) a capacidade de aproveitar as crises para impulsionar a restauração, e (ii) a resiliência dos esforços de restauração para resistir e se recuperar das crises. •Avalie como os diferentes grupos podem ser afetados pelos eventos de crise e pelas respostas de recuperação, incluídos os possíveis impactos desproporcionais nas populações vulneráveis. •Considere se as prioridades de restauração estão alinhadas com os riscos climáticos atuais e futuros, e se os investimentos são avaliados em função de sua viabilidade climática de longo prazo (além das decisões de design técnico). •No contexto das mudanças climáticas, considere tanto os acontecimentos passados quanto os cenários futuros, incluindo o aumento da frequência e intensidade dos choques climáticos. Ferramentas como SPARCLE podem ser utilizadas para visualizar rapidamente os impactos das mudanças climáticas. •Quando pertinente, identifique medidas para mitigar os riscos para a implementação da restauração (por exemplo, planejamento adaptativo, financiamento diversificado, preparação da comunidade). •Embora as crises não sejam desejáveis, quando ocorrem podem oferecer oportunidades para mobilizar o apoio político e comunitário para a recuperação. | L18: ·
B19: d. Requisitos legais | C19: 7. Existem leis e políticas que exigem a restauração. | D19: • Existem leis ou políticas que obriguem os proprietários ou administradores de terras a replantar ou restaurar ecossistemas em áreas que foram desmatadas (por exemplo, florestas, pastagens, zonas úmidas)? | I19: • Existem leis ou políticas que obriguem os proprietários ou administradores de terras a replantar ou restaurar ecossistemas em áreas que foram desmatadas (por exemplo, florestas, pastagens, zonas úmidas)? | J19: O governo possui leis e políticas que exigem que os administradores de terras permitam a recuperação da vegetação natural ou o replantio de árvores em ecossistemas naturais que tenham sido desmatados na área em questão. | K19: • Analise se a legislação exige especificamente a restauração, por exemplo, requisitos de reflorestamento, obrigações de reabilitação de terras ou regulamentos para a restauração de atividades extrativas. Essas leis e políticas especificam quem é obrigado a restaurar, em que situações e por quanto tempo? Este quadro legal aplica-se a todos os limites da área em questão? (Em outras palavras, os requisitos são válidos em todo o país?) • Os requisitos de restauração geralmente são direcionados mais a entidades envolvidas em exploração madeireira comercial, mineração ou outras atividades extrativas do que a atividades de subsistência. | L19: ·
C20: 8. As leis e políticas que exigem a restauração são amplamente compreendidas e aplicadas. | D20: • A lei ou política que exige a restauração de ecossistemas é aplicada de forma visível, credível e justa, e é amplamente compreendida por todos os atores relevantes, incluindo a todos os grupos? | I20: • A lei ou política que exige a restauração de ecossistemas é aplicada de forma visível, credível e justa, e é amplamente compreendida por todos os atores relevantes, incluindo a todos os grupos? | J20: As leis e políticas que exigem a restauração ou reabilitação dos ecossistemas (incluindo as atividades para recuperar as funções dos ecossistemas, reduzir a degradação ou apoiar a regeneração natural) na paisagem-alvo são compreendidas pelos atores pertinentes e aplicadas de forma visível, crível e justa. | K20: •Não basta que exista uma lei ou política que exija a restauração ou reabilitação; é necessário que seja aplicada de forma justa, que as entidades afetadas a compreendam e que as autoridades a implementem para que sirva de motivação para a ação. •Considere se os requisitos legais para a restauração ou reabilitação da paisagem são comunicados às partes interessadas-chave e complementados com ações como campanhas de comunicação, medidas coercitivas (por exemplo, multas) por infrações e a garantia de recursos humanos e financeiros adequados para seu cumprimento. •Os mandatos governamentais de restauração ou reabilitação podem gerar suscetibilidade ao redor da participação do governo em decisões sobre o uso da terra que, de outra forma, estariam sob a jurisdição das comunidades tradicionais ou dos proprietários privados. Portanto, a forma como os requisitos legais são comunicados e complementados com outras políticas, incentivos e práticas pode ser fundamental para sua eficácia. | L20: ·
B21: Condição habilitante | C21: Fator-chave | D21: Pergunta | E21: Resposta | F21: Nacional | G21: Regional | H21: Local | I21: Definição | J21: Orientação | K21: Pergunta(s) complementar(es) | L21: Respostas complementares, justificativa e documentos comprovativos
A22: Habilitar | B22: e. Condições ecológicas | C22: 9. As condições do solo, da água, do clima e do fogo são adequadas para a restauração. | D22: • As condições do solo, a precipitação, a temperatura, os incêndios e a gestão da paisagem pretendida são adequadas para permitir o crescimento e a sobrevivência da vegetação plantada ou de regeneração natural? | I22: As condições de solo, precipitação e temperatura da paisagem em questão são adequadas para o crescimento da vegetação natural, e o regime de incêndios não impede a recuperação dos ecossistemas naturais. | J22: • Este fator-chave combina múltiplas condições ecológicas que afetam a restauração do ecossistema. Cada condição (solo, precipitação, temperatura, incêndios) deve ser avaliada separadamente, mas a resposta pode refletir a soma das quatro. | K22: • Se a resposta for “não”, quais são as deficiências em termos de aptidão física? Será viável tentar superar essas limitações? | L22: ·
C23: 10. Plantas e animais que possam dificultar a restauração são mantidos em níveis mínimos. | D23: • É possível eliminar ou controlar eficazmente plantas e animais invasores indesejados que dificultam a recuperação do ecossistema em paisagens e locais de restauração alvo? | I23: Espécies invasoras persistentes na paisagem em questão podem ser manejadas ou controladas para evitar que interfiram com a vegetação replantada ou em regeneração natural. Áreas de restauração podem ser protegidas do pastoreio de gado, que prejudica a recuperação do ecossistema. | J23: • Considere se existem medidas de monitoramento ou controle (cercas, manejo de ervas daninhas, remoção) para gerenciar espécies problemáticas ou invasoras que possam competir com as espécies utilizadas para restauração ou excluí-las. • As paisagens podem estar livres de plantas e/ou animais indesejados, seja porque nunca existiram naturalmente na paisagem, seja porque foram minimizados com sucesso por meio de manejo. • Alguns exemplos de espécies que podem dificultar os esforços de restauração são Brachiaria spp. no Brasil, Imperata cylindrica na Indonésia, Pueraria montana (kudzu) no sul dos Estados Unidos e animais em pastoreio descontrolado (gado, ovelhas, cabras) em vários locais. | K23: • Caso a resposta seja “não”, quais são as espécies vegetais e/ou animais persistentes e como elas afetam a restauração do ecossistema? | L23: ·
C24: 11. Sementes nativas, mudas ou populações de origem estão facilmente disponíveis. | D24: • A paisagem em questão possui populações-fonte, bancos de propágulos no solo (como sistemas radiculares subterrâneos e bancos de sementes) ou fontes de baixo custo de sementes e mudas nativas que possam servir de base para a recuperação do ecossistema? | I24: A paisagem em questão possui recursos naturais que favorecem a regeneração, como áreas naturais próximas, regeneração de raízes subterrâneas, sementes dispersas por animais e fácil acesso a sementes e mudas nativas de baixo custo que contribuem para a recuperação do ecossistema. | J24: • Populações-fonte viáveis ou bancos de propágulos no solo de plantas nativas são vitais para a restauração passiva. • Este fator-chave de sucesso aplica-se a toda a cadeia de abastecimento de sementes e mudas nativas, incluindo a produção de sementes, a coleta e o processamento de sementes e os viveiros de mudas. | K24: • Se a resposta for “não”, onde está a lacuna (por exemplo, sementes, coletores de sementes, viveiros, populações de origem, bancos de propágulos no solo)? | L24: ·
B25: f. Conditions économiques | C25: 12. Gestão de outras atividades em contraposição à restauração. | D25: • As pressões econômicas derivadas da produção agrícola, pecuária, de lenha e/ou de biocombustíveis sobre as terras degradadas e os ecossistemas naturais na área-alvo estão diminuindo, e/ou existem mecanismos para gerir as demandas econômicas contrapostas sobre a terra que impulsionam sua degradação? | I25: As pressões econômicas derivadas da produção agrícola, pecuária, de lenha e/ou de biocombustíveis sobre as terras degradadas e os ecossistemas naturais na área-alvo estão diminuindo e/ou sendo gerenciadas ativamente por meio de políticas, incentivos, planejamento do uso da terra ou melhorias de produtividade, reduzindo assim as pressões que impulsionam a degradação da terra e "liberando" oportunidades para a restauração. | J25: • As pressões sobre o uso do solo que se contrapõem à restauração podem provir da expansão agrícola, do desenvolvimento de infraestruturas, do pastoreio de gado, da extração de lenha e da urbanização. •Considere se existem mecanismos para gerir essas demandas que se contrapõem à restauração, como o planejamento do uso do solo, o zoneamento, a intensificação agrícola em terras existentes, as intervenções na cadeia de abastecimento, os incentivos à produção sustentável ou as restrições à expansão em ecossistemas naturais. •Este fator-chave de sucesso é possivelmente um dos mais importantes à luz da crescente demanda mundial por terras para produzir culturas, gado e biocombustíveis (Searchinger et al. 2013). •Este fator-chave não se aplicaria quando a terra é restaurada para sistemas agroflorestais ou silvopastoris, que continuam produzindo colheitas e gado, respectivamente. | K25: • Quais são os principais usos alternativos concorrentes da terra para áreas candidatas à restauração? | L25: ·
C26: 13. Existem cadeias de valor e/ou mercados para produtos básicos (madeira, produtos agrícolas) e produtos ambientais (carbono, água, biodiversidade) provenientes de áreas restauradas. | D26: •Existem cadeias de valor, direitos sobre a terra e políticas que permitam que os produtos ou serviços provenientes de terras restauradas cheguem aos consumidores finais? | I26: Na medida em que a restauração florestal na paisagem alvo gerar produtos e serviços comercializáveis, serão estabelecidas cadeias de valor que permitirão que esses produtos cheguem ao consumidor final a partir da floresta restaurada. | J26: • Este fator-chave de sucesso refere-se tanto ao acesso ao mercado quanto à demanda de mercado por produtos e serviços derivados de paisagens florestais restauradas. Uma “cadeia de valor” descreve as múltiplas etapas envolvidas no fornecimento de um produto ou serviço, como colheita, coleta, processamento, transporte e distribuição. Uma cadeia de valor derivada da restauração sugere que indivíduos ou grupos na paisagem em questão podem obter meios de subsistência e desenvolver atividades econômicas locais como parte da restauração do ecossistema. Além disso, as cadeias de valor dos produtos ambientais incluem a geração/fornecimento do serviço, a emissão de créditos de carbono ou de natureza, a compra de créditos, etc. • Analise se existem iniciativas, cooperativas ou empresas nas paisagens visadas que vendem produtos ou serviços como resultado de atividades de restauração. Será que os produtores nesses locais conseguem diferenciar seus produtos e serviços por meio de rótulos, certificações ou acesso a mercados preferenciais? Existe infraestrutura para processar e agregar os produtos e serviços oferecidos pelas regiões-alvo? Existem promotores ou desenvolvedores de projetos que apoiem a geração de créditos de carbono ou de natureza? Quais políticas que facilitam os mercados de carbono e de natureza estão em vigor? • Os serviços ecossistêmicos restaurados podem incluir recreação, turismo e abastecimento de água. | K26: • Se a resposta for “não”, onde estão as lacunas nessa cadeia de valor? • Se a resposta for “sim”, qual é a cadeia de valor, incluindo produtores, intermediários, consumidores finais, etc.? | L26: ·
B27: g. Condições das políticas | C27: 14. Usuários da terra, proprietários de terras ou comunidades têm direitos de posse seguros sobre a terra e seus recursos naturais. | D27: • Os administradores da área em questão possuem direitos claros e seguros para usar a terra, colher produtos de forma sustentável e receber os benefícios financeiros que resultariam da restauração? Esses direitos são acessíveis a todas as partes interessadas, incluindo mulheres e grupos vulneráveis? | I27: As pessoas e comunidades que administram a paisagem em causa têm direitos claros e seguros (por exemplo, sob a forma de propriedade da terra ou direitos de gestão de recursos naturais) aos benefícios que resultariam da restauração. | J27: • A falta (ou insegurança) de posse da terra e de direitos sobre os recursos naturais na paisagem em questão pode desencorajar a restauração que envolva intervenção humana. As pessoas não investirão no plantio de árvores e vegetação nativas nem permitirão a regeneração natural nas terras que administram se não houver probabilidade de se beneficiarem do estado restaurado. • Os direitos de posse e os direitos sobre recursos naturais podem assumir a forma de propriedade privada da terra, terras comunitárias, acordos consuetudinários, certificados de direitos de uso, etc. • Considere também se a posse existente se sobrepõe ou entra em conflito com os direitos consuetudinários. | K27: • Se a resposta for “não”, quais direitos estão faltando e para quem? | L27: ·
C28: 15. As políticas que afetam a restauração são harmonizadas e simplificadas. | D28: • As políticas que podem ter impacto na restauração da paisagem alvo estão alinhadas e otimizadas em um contexto global, nacional, subnacional e local? | I28: As políticas públicas relevantes estão alinhadas, são consistentes e otimizadas para apoiar eficazmente os esforços de restauração na área-alvo. Essas políticas se reforçam mutuamente, minimizam barreiras administrativas desnecessárias e criam um ambiente propício à sua implementação. Políticas que promovam a igualdade de gênero e a inclusão social também são consideradas essenciais para apoiar resultados de restauração inclusivos e sustentáveis. | J28: • As políticas nacionais sobre clima, biodiversidade e degradação do solo provavelmente terão pontos de convergência para a restauração, que podem ser considerados por meio dos comitês nacionais existentes. • Outras políticas a serem consideradas incluem aquelas relacionadas à agricultura, indústrias extrativas, água, planejamento do uso da terra, infraestrutura e recursos naturais. • Em alguns casos, as políticas de conservação da natureza ou outros setores podem inibir a restauração (por exemplo, leis que proíbem a remoção de sementes nativas de áreas protegidas, leis que proíbem a colheita de espécies arbóreas nativas, subsídios que incentivam fatores de degradação). | K28: • Se a resposta for “não”, quais políticas não estão alinhadas ou simplificadas? | L28: ·
C29: 16. Existem restrições à exploração madeireira nos ecossistemas naturais remanescentes (florestas, pastagens, zonas úmidas, etc.). | D29: • A área em questão possui leis que restringem a exploração madeireira ou o desmatamento dos ecossistemas naturais remanescentes? | I29: A área em questão possui leis que restringem o desmatamento ou a exploração madeireira dos ecossistemas naturais remanescentes. | J29: • Restrições à exploração madeireira em florestas remanescentes e ecossistemas naturais podem impedir a expansão de áreas degradadas ou exploradas. Essas restrições também criam um incentivo para restaurar a produtividade de áreas já exploradas, uma vez que as oportunidades de utilização da fronteira florestal são reduzidas. • As restrições também podem assumir a forma de uma extensa rede de parques nacionais e florestas nacionais, uma extensa rede de territórios indígenas florestados, padrões de proteção de ecossistemas em terras comunitárias, padrões de “perda líquida zero”, percentuais específicos de terra que devem permanecer como floresta (por exemplo, o Código Florestal do Brasil) e muito mais. • Um componente importante desse fator-chave de sucesso é que as “florestas e ecossistemas naturais” foram claramente definidos pela jurisdição que patrocina a restrição (por exemplo, o governo nacional). Essa definição deve incluir florestas primárias, florestas secundárias, florestas degradadas e outros ecossistemas com potencial de restauração. Nota: Os possíveis efeitos de deslocamento ou vazamento (por exemplo, o deslocamento do desmatamento para outras áreas) são abordados em uma seção separada desta avaliação e devem ser considerados em conjunto com esta pergunta. | K29: • Se sim, quais são essas leis? | L29: ·
C30: 17. Existem restrições à exploração madeireira em ecossistemas naturais remanescentes (por exemplo, florestas, pastagens, zonas úmidas). | D30: • Estas restrições de desmatamento ou corte são adequadamente aplicadas? | I30: As leis que restringem a exploração madeireira dos ecossistemas naturais remanescentes são devidamente aplicadas. | J30: • Não basta ter regulamentos que restrinjam a exploração madeireira dos ecossistemas naturais remanescentes; é necessário que as autoridades competentes façam cumprir essas restrições. • Particularmente em áreas remotas, a aplicação da lei depende da capacidade das organizações policiais e dos incentivos que estas possuem para desempenhar suas atividades. | K30: • Se a resposta for "não", por quê? | L30: ·
B31: h. Condições sociais e culturais | C31: 18. Mulheres, jovens e povos indígenas participam da tomada de decisões sobre a restauração. | D31: • As mulheres, os jovens e os povos indígenas que vivem na área-alvo e em seus arredores, juntamente com os sistemas culturais, as estruturas de governança tradicional e os sistemas de conhecimento que representam, estão envolvidos de forma significativa na tomada de decisões sobre a restauração (por exemplo, concepção do programa, definição de metas, gestão, monitoramento e seleção de indicadores)? | I31: Mulheres, jovens e povos indígenas são explicitamente reconhecidos e apoiados como participantes-chave no planejamento e implementação da restauração em todas as escalas. Seus sistemas culturais, estruturas de governança tradicionais e conhecimentos são respeitados e integrados aos órgãos de tomada de decisão, acordos de governança e processos de monitoramento, garantindo resultados de restauração inclusivos, representativos e culturalmente adequados. | J31: • A tomada de decisões relacionadas a essas áreas (incluindo planejamento, projeto, gestão e monitoramento) deve ser inclusiva e culturalmente adequada. Quando a participação é limitada ou extrativista, os esforços de restauração correm o risco de fragmentação, enfraquecimento da apropriação local e distribuição desigual dos benefícios, especialmente para mulheres, jovens e povos indígenas. • Aproveitar e fortalecer as instituições locais existentes e os processos culturalmente enraizados (por exemplo, cooperativas florestais a nível de aldeia, grupos de mulheres, organizações de povos indígenas, associações de jovens e sistemas de governação tradicionais) pode apoiar os acordos de cogestão, melhorar a participação local e aumentar a adoção a longo prazo de iniciativas de restauração. • O planejamento e a implementação da restauração devem reconhecer e respeitar os sistemas culturais em geral (incluindo os valores, o conhecimento e as práticas de diversos grupos de partes interessadas) e integrar essas perspectivas nos processos de tomada de decisão, gestão e monitoramento. • A participação efetiva e inclusiva exige transparência e responsabilização na tomada de decisões, respeito pelo consentimento livre, prévio e informado (CLPI), quando apropriado, e mecanismos de reclamação e feedback acessíveis e confiáveis que permitam às partes interessadas expressar preocupações e possibilitar a correção de rumos quando os processos ou resultados falharem. | K31: • Se a resposta for "não", quais grupos não estão bem representados? • Se a resposta for "não", de que aspectos da restauração os grupos vulneráveis são excluídos? | L31: ·
C32: 19. A população local se beneficia com a restauração. | D32: • As pessoas que vivem na área-alvo e em seus arredores podem usufruir dos benefícios gerados pela restauração, como a melhoria dos meios de subsistência ou dos serviços ecossistêmicos? | I32: As comunidades que vivem dentro ou ao redor das áreas-alvo têm suas necessidades atendidas por meio de esforços de restauração e recebem benefícios ambientais (por exemplo, melhoria da qualidade da água, aumento da oferta de produtos florestais) ou benefícios econômicos (por exemplo, fontes alternativas de renda, melhoria dos meios de subsistência) como resultado da restauração. | J32: • A documentação de planejamento e o projeto técnico de qualquer iniciativa de restauração devem incluir estruturas e mecanismos para garantir que as pessoas que vivem nas áreas restauradas ou em suas proximidades sejam as principais beneficiárias dos resultados positivos da restauração. Aqui você encontrará exemplos dos benefícios que a restauração pode trazer. • Os planejadores ou executores de restaurações devem se perguntar continuamente: Entre os benefícios sociais, culturais, políticos, ambientais e econômicos identificados, os planos de restauração especificam quais pessoas ou grupos locais devem se beneficiar das atividades de restauração? Esses benefícios correspondem às necessidades locais? Os benefícios recebidos pela população local são razoáveis, equitativos e confiáveis? • Se a população local não perceber os benefícios, terá poucos incentivos para mudar seus comportamentos a fim de possibilitar a restauração ou sustentar a paisagem restaurada a longo prazo. | K32: • Se a resposta for “não”, quais barreiras ou limitações impedem as comunidades locais de aceder aos benefícios da restauração? | L32: ·
B33: i. Condições institucionais | C33: 20. Os papéis e responsabilidades na restauração estão claramente definidos. | D33: Os papéis e responsabilidades na restauração do ecossistema na paisagem em questão estão claramente definidos, são compreendidos pelas partes interessadas relevantes e contam com o apoio das autoridades? | I33: Os papéis e responsabilidades para a restauração na paisagem alvo estão claramente definidos, são compreendidos entre os atores relevantes (por exemplo, governo, sociedade civil, setor privado e outras partes interessadas relevantes) e contam com o apoio da autoridade competente. | J33: • Analise se existem agências, instituições ou grupos designados com poder para implementar a restauração de ecossistemas. • Na ausência de clareza sobre funções e responsabilidades, a inação pode ocorrer porque funções importantes não são contempladas, há incerteza sobre quem faz o quê, ou instituições e grupos reivindicam responsabilidades e direitos sobrepostos. • Para responder adequadamente a esta questão, os usuários podem precisar mapear os mandatos existentes para o planejamento, a coordenação, a implementação e o monitoramento da restauração entre entidades públicas, grupos e organizações privadas, proprietários de terras, usuários da terra e outras partes interessadas importantes. Funções, responsabilidades e direitos também podem ser definidos em leis, políticas ou práticas consuetudinárias. | K33: • Se a resposta for “não”, o que está faltando em termos de clareza de funções e responsabilidades? | L33: ·
C34: 21. Mantém-se uma coordenação institucional eficaz. | D34: As partes interessadas pertinentes do governo, da sociedade civil e do setor privado — por exemplo, por meio de um grupo de trabalho ou de um processo multilateral — coordenam-se de forma eficaz para conceber, implementar e supervisionar a restauração do ecossistema na área candidata, garantindo ao mesmo tempo que esses esforços incluam os grupos vulneráveis? | I34: Os atores relevantes do governo, da sociedade civil e/ou do setor privado estão suficientemente coordenados para planejar, implementar e monitorar a restauração na área-alvo. | J34: • Analise se as instituições públicas e privadas se comprometeram a estabelecer uma liderança e mandatos claros para a restauração. Existe alguma ação conjunta comprovada, na forma de mecanismos de coordenação, comitês, grupos de trabalho ou alianças, que se reúnam regularmente e tomem decisões sobre a restauração? Esses esforços de coordenação incluem planos compartilhados, dados, contribuições técnicas e monitoramento, especialmente entre os níveis de governança local, regional e nacional? | K34: • Se a resposta for “não”, o que está faltando em termos de coordenação? | L34: ·
B35: Condição habilitante | C35: Fator-chave | D35: Pergunta | E35: Resposta | F35: Nacional | G35: Regional | H35: Local | I35: Definição | J35: Orientação | K35: Pergunta(s) complementar(es) | L35: Respostas complementares, justificativa e documentos comprovativos
A36: Implementar | B36: j. Liderança | C36: 22. Existem líderes nacionais e/ou locais de restauração | D36: • Existe algum defensor carismático e comprometido com a restauração na área em questão? Eles representam todos os segmentos da sociedade, incluindo mulheres, jovens e povos indígenas? | I36: Existem pessoas carismáticas (ou instituições influentes) que podem inspirar eficazmente os responsáveis pela tomada de decisões a perseguir a restauração, mobilizar apoios e manter o impulso ao longo do tempo na área candidata | J36: • Os líderes locais da restauração podem ser pessoas ou grupos comprometidos com a restauração da área e capazes de agir em conformidade. Em algumas paisagens ou ecossistemas, pode ser necessário destacar os líderes de restauração e dar-lhes um perfil visível. • Historicamente, projetos de restauração bem-sucedidos contaram com um promotor ou forte apoio governamental. Poucos não possuíam ambos. | K36: • Quem é (são) o(s) líder(es) local(is) da restauração?
C37: 23. Existe um compromisso político contínuo. | D37: • Existe um compromisso claro e sustentado a longo prazo por parte de instituições governamentais e não governamentais para apoiar os esforços de restauração na área em questão? | I37: O compromisso das autoridades governamentais (em todos os níveis relevantes, quando apropriado) e das instituições não governamentais com a restauração na área-alvo está claramente estabelecido e reconhecido como um compromisso sustentado a longo prazo. | J37: • Pode ser difícil prever o compromisso de longo prazo de um governo ou organização. Em situações como essa, é necessário considerar se o compromisso transcende os partidos políticos e se a restauração trará benefícios recorrentes para os principais interessados. | K37: • Em caso afirmativo, qual é a prova do compromisso expresso e de quem ele partiu?
B38: k. Conhecimento | C38: 24. Existem "conhecimentos técnicos" de restauração pertinentes para a área candidata | D38: • Existe conhecimento local diversificado (incluindo conhecimento indígena, conhecimento ecológico tradicional e conhecimento sensível às questões de gênero) sobre como implementar a restauração em larga escala na paisagem em questão? | I38: Especialistas locais conhecem as técnicas de restauração (por exemplo, regeneração natural e assistida, conhecimento tradicional) adaptadas à paisagem em questão, ou realizam pesquisas sobre o assunto. | J38: • O conhecimento local pode vir do saber tradicional das comunidades que vivem dentro ou ao redor da paisagem, de especialistas em universidades e serviços de extensão rural, e de organizações não governamentais atuantes nessa área. • O conhecimento pode ser gerado localmente ou importado de outros lugares, mas deve ser comunicado ou transmitido por profissionais locais. Orientações sobre as “melhores práticas” em restauração podem ser obtidas em universidades, organizações não governamentais ou agências de extensão rural, bem como com indivíduos ou grupos locais com experiência em restauração a longo prazo. | K38: • Caso a resposta seja “não”, quais são as lacunas de conhecimento mais significativas?
C39: 25. O conhecimento técnico da restauração é transferido por meio de parceiros ou serviços de extensão. | D39: • Existem serviços de extensão rural, visitas de agricultor para agricultor, grupos de mulheres, redes locais e/ou outros meios de sensibilização e capacitação para a restauração, e estes dispõem de recursos adequados na área-alvo ou a nível nacional? | I39: Dispõe-se de assistência técnica e extensão rural ("serviços de extensão"), visitas de agricultor a agricultor, grupos de mulheres, redes locais e/ou outros meios de conscientização e desenvolvimento de capacidades para a restauração, e conta-se com os recursos adequados na área candidata. | J39: • A partilha de conhecimento pode ser documentada em serviços formais de extensão, tais como visitas de campo, programas de formação, escolas de campo, materiais impressos e locais de demonstração. • Analise se os grupos informais de aprendizagem sobre restauração estão compartilhando informações ou coordenando atividades, incluindo grupos de mulheres, associações de produtores ou troca de conhecimento entre povos indígenas. Essa comunicação "de agricultor para agricultor" ou "de gestor de terras para gestor de terras" pode ser um dos meios mais eficazes de educação e treinamento. • Redes ou associações locais para o desenvolvimento de capacidades em restauração de ecossistemas, agroflorestamento ou reflorestamento podem ser mencionadas em documentos nacionais ou relatórios de organizações não governamentais. | K39: • Considerando o panorama atual de candidatos, quais entidades estão melhor posicionadas para fornecer serviços de extensão?
B40: l. Design técnico | C40: 26. O design da restauração tem uma base técnica e adaptada às mudanças climáticas | D40: • O plano de restauração da paisagem em questão baseia-se nas melhores práticas, incorporando a melhor ciência disponível, o conhecimento ecológico tradicional e abordagens resilientes às mudanças climáticas? | I40: O plano de restauração da paisagem candidata baseia-se nas melhores práticas para o projeto, implementação e manutenção de atividades de restauração. O plano de restauração da paisagem incorpora as melhores práticas científicas disponíveis e abordagens resilientes ao clima, garantindo que a intervenção, incluindo aspectos como a seleção de espécies e as técnicas de restauração, seja adequada ao contexto local e aos objetivos da intervenção, e reduza a vulnerabilidade da intervenção de restauração aos impactos climáticos, como secas, inundações, incêndios florestais e temperaturas extremas. | J40: • Avalie se as abordagens para a restauração de ecossistemas são apoiadas por pesquisas científicas, conhecimento local ou práticas indígenas para restaurar ecossistemas naturais e reduzir a vulnerabilidade aos impactos climáticos. • O projeto técnico deve abordar aspectos como preparação do terreno, declive, seleção de espécies, espaçamento e manutenção das árvores, ou como eliminar as pressões que impedem o crescimento da vegetação natural (por exemplo, gado, incêndios). • Os planos de restauração devem levar em consideração os impactos climáticos projetados para serem resilientes às mudanças climáticas. | K40: • Se a resposta for “não”, o que está faltando no plano?
C41: 27. A restauração limita os "vazamentos" | D41: • O processo de restauração possui disposições estabelecidas (por exemplo, políticas, práticas, incentivos, melhorias de desempenho) que limitam os vazamentos ou está sendo desenvolvido de forma a reduzi-los? As atividades de restauração impedem que os usuários da terra sejam deslocados para outras áreas onde não têm outra opção senão transformar/limpar os ecossistemas naturais para uso agrícola? | I41: A restauração dos ecossistemas na paisagem candidata impede a transferência das atividades de desmatamento para outros locais ("vazamento"), resultando em um aumento líquido da área restaurada. | J41: • Existe o risco de que a restauração do ecossistema na paisagem alvo possa resultar no deslocamento das atividades que estavam causando a degradação do solo para alguma outra paisagem. • Embora esse “vazamento” possa resultar em um aumento da área restaurada na paisagem alvo, também resultaria em um aumento de terras degradadas ou desmatadas em outros locais. • Algumas maneiras de limitar vazamentos decorrentes de atividades de restauração podem incluir: Combinar a restauração com usos produtivos (por exemplo, agroflorestamento), fornecer alternativas de subsistência locais que não exijam a conversão de terras em terras agrícolas, aumentar a eficiência agrícola para que a produção não se desloque para novas áreas, planejar a restauração em nível de paisagem para gerenciar as mudanças nas atividades e abordar os fatores subjacentes à degradação. • Para obter mais informações sobre o reflorestamento em um país que desloca o desmatamento para outro, consulte: Meyfroidt e Lambin (2011). | K41: • Caso a resposta seja “não”, quais medidas estão faltando no processo de restauração para evitar o deslocamento da degradação do solo para outras áreas?
