Workbook

Sheet Instructions
A1: Restoration Diagnostic
A2: Verson 2.0 - Updated 2026
B4: Overview | H4: How does the Diagnostic work? | N4: Other considerations
B5: Welcome to the WRI Restoration Diagnostic! A rapid assessment tool to evaluate the readiness of a geography or scale for restoration and design strategic actions to ensure long-term success. A stand-alone tool developed as part of ROAM (Restoration Opportunities Assessment Methodology) https://iucn.org/resources/grey-literature/guide-restoration-opportunities-assessment-methodology-roam | H5: The diagnostic follows a three-step process, with a previous section before you get started strongly suggested. Plus a suggested preparatory step. See “Before you get started” tab. Each step corresponds to a section of the tool with each step explained on a separate tab of this document: Step 1. Define the scope; Step 2. Assess the key factors for restoration; Step 3. Propose actions to address gaps The "Summary Table" tab produces a summary table based on your inputs to Steps 1, 2 and 3. | N5: Suggested Timeline for Applying the Diagnostic Step 1. Define the Scope 2-3 Days Step 2. Assess the key factors for restoration 2-4 Weeks Step 3. Select actions to address gaps 2-3 Weeks The suggested timeline provides an indicative estimate of the time required to apply the diagnostic. The actual duration may vary depending on the context, scope of the assessment, availability of information, stakeholder engagement processes, and the time allocated by the implementing team. In some cases, steps may take longer if additional consultations, data collection, or validation are needed. Conversely, the process may move more quickly when information and stakeholders are readily available.
B10: What is the Restoration Diagnostic Tool? The Restoration Diagnostic helps you assess whether the cultural, financial, political, institutional, and ecological key factors are in place for ecosystem restoration to thrive. By identifying gaps and challenges, you can move from general planning to targeted, effective action.
B14: Why is this tool useful? A diagnostic helps identify the key factors that influence restoration success and informs more strategic planning and action.
B17: Am I the right person to use this tool? You should use this tool if you are responsible for planning or coordinating national or sub-national restoration policies, actions, and measures and want to understand the current state of conditions for successful restoration.
N19: What is the final outcome of this diagnostic? The diagnostic results in a shared understanding of the key factors influencing restoration success and a prioritized set of actions to strengthen those factors and enable restoration in the target geography or scale.
H21: The "Additional guidance" column provides further explanation of each key factor to guide your answers in Step 2.
B22: Note on Participation: While one person can lead the data entry, the tool is most effective when used participatorily, gathering perspectives from diverse stakeholders and experts.
B27: What are the key factors? Key factors are the conditions and elements that influence whether restoration efforts can succeed and be sustained over time. For example, these factors include the benefits provided by restoration, available knowledge on restoration, market and policy conditions for restoration, and more. For reference, a full list of enabling conditions and key factors is included in Step 2.
N29: Documents to gather in advance (non-exhaustive) + National restoration plans, strategies, or programs + Restoration commitments under UNFCCC, UNCBD, UNFCCC + Restoration-related laws or policies for forestry, agriculture, or other relevant ecosystems + Sub-national documentation of restoration actions + Municipal development plans in the target landscapes
H30: If you need more information about how this tool was prepared, a detailed written explanation of the diagnostic is available online at: XXXX

Sheet Before you get started
B1: Step 1. Define the Scope
B3: Before You Get Started
B4: Why complete this phase? This preparation phase helps ensure the diagnostic runs smoothly and produces results that stakeholders trust and can act on. It helps ensure: Alignment: Roles and responsibilities are clear. Inclusion: Relevant stakeholders are involved. Efficiency: Key information and documents are ready.
B6: How to complete this phase
B7: 1. Appoint a Process Lead Designate a person responsible for coordinating the diagnostic and consolidating results. 2. Define Stakeholder Engagement Choose how stakeholders will contribute: Workshops for group discussions and rapid alignment Interviews for some topics Distributed input for technical experts contributing remotely 3. Gather Key Materials Collect relevant documents and data to support the assessment
B9: Designing stakeholder engagement
B10: Start by mapping the social landscape around restoration: who the users are, who is affected, and who has influence. Identify stakeholder needs, motivations, and relationships to understand where friction or alignment may occur. Use this insight to design engagement touchpoints—workshops, interviews, feedback loops—that are inclusive, iterative, and responsive to context. Treat stakeholders as co-designers, not just data sources, to improve usability, relevance, and adoption of the tool. Suggested mapping social landscapes tool https://www.wri.org/research/mapping-social-landscapes-guide-identifying-networks-priorities-and-values-restoration
B17: Suggested Documents to Gather (non-exhaustive)
B18: □ A. Policy & Legal Context [ ] National restoration strategies or programs. [ ] Laws and regulations (Forestry, Agriculture, Land Use, Water). [ ] International commitments (UNFCCC, CBD, UNCCD). [ ] National development plans and NDCs. □ B. Implementation & Planning [ ] Sub-national or regional restoration action plans. [ ] Municipal development plans for the target landscapes. [ ] Donor-funded program documentation. [ ] Existing institutional budgets and organizational charts. □ C. Biophysical & Socioeconomic Data [ ] Land cover and land degradation assessments. [ ] Restoration opportunity maps (e.g., ROAM outputs). [ ] Socioeconomic data (tenure status, livelihood dependence, market analyses). □ D. Monitoring & Baselines [ ] Data from landscape monitoring systems (e.g., Global Forest Watch). [ ] Existing restoration indicators and historical progress reports.
B20: Ensuring inclusion and equity
B21: Some participants may hesitate to share in group settings, and local social/gender dynamics can exclude some groups. The coordinating team should adapt engagement methods to ensure diverse perspectives are captured. This can be done by: • holding separate focus groups for women and/or Indigenous communities • using local languages • including trusted intermediaries • providing travel/compensation where needed • creating safe space agreements • allowing anonymous written input for sensitive questions

Sheet Step 1. Define the Scope
B1: Step 1. Define the Scope
B3: Why this step is important?
B4: In this step you can take time to clearly define the scope of the assessment. This includes deciding where the diagnostic will take place, the timeframe you are planning for, and the goals of restoration in the landscape. Making these decisions early helps ensure the diagnostic focuses on the right issues, stakeholders, and restoration opportunities.
B7: Choose the Geographic Area & Ecosystem Types
B8: Define the geography, scale or landscape where the diagnostic will take place. Selecting the right geographic scope is important because it determines which ecosystems will be assessed, which stakeholders need to be involved, and which restoration options are relevant. This may include: National Subnational (i.e., municipality, province, district) Landscape (or seascape if applicable) Restoration site Transboundary (i.e., two or more countries)
B14: Capture Ecosystem Types
B15: The list of ecosystems below is indicative.
B16: Reference: IUCN Global Ecosystem Typology 2.0
B17: https://portals.iucn.org/library/sites/library/files/documents/2020-037-En.pdf, https://global-ecosystems.org/
B18: Terrestrial | F18: Freshwater | I18: Marine
B19: Tropical-subtropical forests | F19: Peatlands | I19: Marine shelfs
B20: Temperate-boreal forests and woodlands | F20: Wetlands | I20: Mangroves and shoreline systems
B21: Shrublands and shrubby woodlands | F21: Riparian ecosystems | I21: Deep-sea floors
B22: Savannas and grasslands | F22: Catchments
B23: Deserts and semi-deserts | F23: Artificial fresh waters
B24: Polar-alpine
B25: Productive and agricultural systems
B26: Urban Landscapes
B28: Set the Time Horizon
B29: Decide how far into the future the restoration effort is planning. Restoration is a long-term process. While some benefits may appear early, many ecological and social outcomes take years to materialize. Defining a clear time horizon helps set realistic expectations and ensures that restoration efforts align with existing policies and planning cycles. Aim for a long-term vision, even if actions begin in the short term. Where possible, align the timeframe with national or regional planning frameworks.
B31: Define Restoration Goals
B32: Clarify what you want restoration to achieve in the landscape. Restoration goals may focus on a single ecosystem (such as forests or mangroves) or on a mix of ecosystems and land uses, including agriculture or agroforestry systems. Goals can be described either before or after running the diagnostic, depending on the context and how the diagnostic is completed. Common restoration goals include (non-exhaustive): - Biodiversity conservation - Climate mitigation or adaptation - Improved livelihoods - Water security - Food production Clearly defined goals help guide which restoration options are considered and help stakeholders agree on what success will look like.
B34: Validate the Scope with Stakeholders
B35: Before moving forward, confirm the scope with relevant stakeholders. Early validation helps build trust, shared understanding, and ownership of the diagnostic process. It also helps ensure that the assessment reflects local priorities and realities.

Sheet Step 2. Assess Key Factors
A1: Step 2. Assess key factors for restoration by selecting a response for each question below. A definition and follow up questions are provided to gather additional context.
B3: Purpose Step 2 assesses whether the key success factors for ecosystem restoration are currently: • In place • Partly in place • Not in place The objective is not to produce an exhaustive breakdown of every aspect of the restoration process, but rather to rapidly identify strengths, weaknesses, and potential bottlenecks to successful restoration. Structure of the Assessment The assessment is organized around three overarching themes: 1. Motivate – Factors that inspire or motivate to catalyze processes that lead to restoration 2. Enable – Factors that create a favorable context for restoration 3. Implement – Factors related to capacities and resources to mobilize the implementation of restoration on-the-ground | J3: The color coding means the following:
J4: Green = IN PLACE
J5: Yellow = PARTLY IN PLACE
J6: Red = NOT IN PLACE
J7: White: NOT APPLICABLE
B12: Enabling condition | C12: Key Factor | D12: Diagnostic question | E12: Response | F12: National | G12: Regional | H12: Local | I12: Definition | J12: Guidance for the diagnostic question | K12: Follow up question(s) | L12: Follow up responses, rationale and supporting documents
A13: Motivate | B13: a. Benefits | C13: 1. Restoration generates economic benefits | D13: • Is restoring the target area expected to generate economic benefits that result in a net positive financial or economy-wide economic impact relative to the status quo land use? | I13: Restoring the candidate area is expected to yield economic benefits (e.g., economic diversification, avoided damages, new marketable products) that create a net positive financial impact (private benefits) and/or net positive economy-wide impact (public benefits) relative to the status quo land use. Side note: “economic impacts referring to environmental benefits that function as public goods, or to economy-wide economic impacts that capture restoration-related spillovers across value chains and the broader economy, including GDP growth and employment. Such impacts typically arise from economic benefits like diversification, avoided damages, and new market products enabled by restoration. | J13: • Economic benefits from restoration are the overall positive outcomes for income or finance that result from implementing restoration activities versus a business-as-usual scenario. • Examples of economic benefits include increased income, improved entrepreneurship opportunities, increased production of key commodities, or new employment opportunities that result from restoration efforts. A more complete list of possible benefits is included in this tool in the “Restoration Benefits” table. • The timeframe of this answer should consider the timeframe of the anticipated restoration activities, recognizing that restoration processes and their benefits occur over the long-term. • Make note of which individuals or groups would likely receive these benefits. • Some landowners may be concerned that “restoration” means they will lose their land, user rights, or income relative to the status quo. Therefore, the answer to this question can be supported with documents that show how the net benefits outweigh the costs.Side note: formalized land rights might emerge as a positive co-benefit of the restoration project. In some cases, implementing the project and disbursing finance to support restoration activities may require clear land rights to be clearly defined. Consequently, this could accelerate demarcation processes and enable local communities to obtain legal title to their land. | K13: • If “yes”, then what are the expected economic benefits? • If “yes”, then who benefits? • If “no”, then how big is the expected financial or economic gap? | L13: ·
C14: 2. Restoration generates social benefits | D14: • Is restoring the target area expected to generate social, cultural, or political benefits for the people living in that area, including vulnerable groups such as women, youth and Indigenous people? | I14: Restoring the target area is expected to improve livelihoods, elevate the social or political standing of vulnerable populations, safeguard or restore natural cultural heritage sites or the use of culturally significant practices, or yield other social, cultural, and/or political benefits for the local population. | J14: • Review the list of possible social benefits in the "Restoration Benefits" table found in the supporting materials for this tool. For example, restoration activities may result in benefits that are social, cultural or political in nature, such as increased visibility of cultural values, recognition of traditional ecological knowledge, achievement of political gains, increased recreational opportunities, or improvements in gender equity. Restoration can also be a way for governments to be seen as leaders on the global stage and achieve commitments to international agreements (e.g., UNFCCC, UNCCD, UNCBD, REDD+, SDGs). Furthermore, restoration can be beneficial to countries or communities with a historical cultural connection to forests or other ecosystems (e.g., forest-based traditions and folklore, ecosystem-based livelihoods and employment). • Consider whether the benefits list in the table are recognized or considered in restoration plans, programs, or activities in the target landscape. • Make note of which individuals or groups would likely receive these benefits. | K14: • If “yes”, then what are the expected social benefits? | L14: ·
C15: 3. Restoration generates environmental benefits | D15: • Is restoring the target area expected to generate environmental benefits? | I15: Restoring the target area is expected to generate substantial and long-term environmental benefits, including the conservation and recovery of biodiversity, enhanced climate change mitigation and adaptation, reduced land degradation and desertification, and the restoration of vital ecosystem services such as water regulation, soil fertility, and carbon sequestration. These improvements will contribute to increased ecological resilience and sustainable livelihoods over time. | J15: Examples of environmental benefits include enhanced biodiversity, improved watershed security, strengthened climate change mitigation and adaptation, and increased soil fertility, among others. A more comprehensive overview of anticipated environmental benefits is provided in the supporting materials for this diagnostic, in the “Restoration Benefits” table. | K15: • If “yes”, then what are the expected environmental benefits? | L15: ·
B16: b. Awareness | C16: 4. Benefits of restoration are publicly communicated | D16: • Are the benefits of restoring the target area communicated to all stakeholders, including groups such as women, youth and Indigenous People, and communication channels designed to reach these diverse stakeholders? | I16: The benefits of restoring the target landscape have been clearly communicated to land managers, all groups, and other relevant stakeholders | J16: • Communication may be through various channels, including articles, press, social media, radio and television, demonstration visits, street plays or other pathways that target relevant stakeholders and decision makers. • Peer-to-peer communication of restoration benefits can be an effective means of raising awareness and motivating action. • Consider whether this communication is organized as part of a larger stakeholder engagement strategy. • A more complete list of benefits is included in the supporting materials to diagnostic in the “Restoration Benefits” table. | K16: • What benefits might arise? • How has the communication specifically targeted or included key stakeholders? | L16: ·
C17: 5. Opportunities for restoration are identified | D17: • Have target or priority areas for restoration been identified and quantified? | I17: Candidate areas for restoration have been identified and quantified. | J17: • Target areas for restoration are the places where restoration efforts should occur based on a combination of environmental, social, and economic considerations. • Information on these opportunities may be presented in national or subnational maps and/or restoration strategies, and should be consistent with the areas that government agencies use when allocating funding, programs, planning resources for restoration. • Consider whether stakeholders recognize and reference the same priority levels. | K17: • If “yes”, then where are the candidate areas? • If “yes”, then how big is the restoration opportunity? | L17: ·
B18: c. Crisis events | C18: 6. Crisis events are leveraged | D18: • Is the target area experiencing a crisis event, or the risk of one in the future, that would motivate restoration in the target landscape, and how could those events affect the different groups of population (rural and peasants, urban, indigenous, women, youth, etc) and be anticipated? | I18: The government and/or civil society use the risk or occasion of crisis events, including considering future scenarios (including climate), to build political and public support for ecosystem restoration. | J18: • Crisis events can include floods, landslides, droughts, fires, sandstorms, wood shortages, declining crop yields, and unemployment, among others. Crises can include humanitarian catastrophes where damage could have been avoided if natural ecosystems were intact (e.g., a landslide), where the act of restoration could address the crisis (e.g., unemployment), or where restoration prevents future crises (e.g., floods). • iConsider including an earlier strategic check on whether restoration priorities are aligned with future climate scenarios, and whether restoration investments are screened for long-term climate viability (beyond technical design choices). • One does not desire these events to occur. But when they do occur, restoration supporters should act quickly to mobilize political and community support for restoration. • In the context of climate change and resilience, be sure to consider both past climate impacts as well as future scenarios and to plan accordingly, where thresholds must now be calculated more broadly. | K18: • What types of crises have occurred in the target landscape in the past? • What types of crises could occur in the future? | L18: ·
B19: d. Legal requirements | C19: 7. Laws and policies requiring restoration exist | D19: • Are law or policies in place requiring land owners or managers to replant or restore ecosystems in areas that have been cleared (e.g., forests, grasslands, wetlands)? | I19: The government has legislation and policies that require land managers to allow for recovery of natural vegetation or to replant trees in natural ecosystems that have been cleared in the candidate landscape. | J19: • Consider whether legislation specifically mandates restoration, such as requirements for reforestation, obligations to rehabilitate land, or restoration regulations on extractive activities. Do these laws and policies specify who is required to restore, in what situations, and over what timeframes? Does this legal framework apply over the full boundaries of the target area? (I.e., are the requirements national in scope?) • Restoration requirements are more commonly directed at entities involved with commercial logging, mining, or other extractive activities than for subsistence activities. | K19: • If “yes”, what specific terms and conditions does the law have (e.g., what to restore, by when, how)? | L19: ·
C20: 8. Laws and policies requiring restoration are broadly understood and enforced | D20: • Is the law or policy requiring ecosystem restoration enforced in a visible, credible, and fair manner and broadly understood by all relevant actors, including vulnerable groups? | I20: The laws and policies requiring tree recovery or replanting in the target landscape are understood by relevant actors and are enforced in a visible, credible, and fair manner. | J20: • It is not sufficient that a law requiring restoration merely exists; the law needs to be enforced fairly and understood by affected entities and enforced by authorities if it is to motivate restoration. • Consider whether the legal requirements for landscape restoration are communicated to key stakeholders and complemented by actions like communication campaigns, enforcement efforts (e.g., fines) for violation of restoration requirements, and ensuring adequate human and financial resources for enforcement. • Government mandates for restoration can trigger sensitivities about government involvement in land-use decisions that otherwise would be the purview of traditional communities or private landowners. Therefore, how legal requirements are communicated and complemented by other policies, incentives, and practices can be important for the success of the requirement. | K20: • If “no”, then what is the nature of the shortcoming? | L20: ·
B21: Enabling condition | C21: Key Factor | D21: Diagnostic question | E21: Response | F21: National | G21: Regional | H21: Local | I21: Definition | J21: Guidance for the diagnostic question | K21: Follow up question(s) | L21: Follow up responses, rationale and supporting documents
A22: Enable | B22: e. Ecological conditions | C22: 9. Soil, water, climate, and fire conditions are suitable for restoration | D22: • Are the target area soil, rainfall, temperature, and fire and management conditions suitable for enabling growth and survival or planted or naturally regenerating vegetation? | I22: The target area´s soil, rainfall, and temperature conditions are suitable for regrowth of natural vegetation, and the fire regime does not hinder recovery of natural ecosystems. | J22: • This key factor combines multiple ecological conditions affecting ecosystem restoration. Each condition (soil, rainfall, temperature, fire) should be evaluated on its own, yet the response can reflect the aggregate of the four. | K22: • If “no”, then what are the gaps in physical suitability? | L22: ·
C23: 10. Plants and animals that can impede restoration are minimized | D23: • Can unwanted invasive plants and animals that hinder ecosystem recovery be effectively removed or controlled In the target area and restoration sites? | I23: Persistent invasive species in the target area can be managed or controlled to avoid interference with replanted or naturally regenerating vegetation. Restoration sites can be protected from grazing livestock that impede ecosystem recovery. | J23: • Consider whether there are monitoring or control measures (fencing, weed management, removal) in place to manage problematic or invasive species that can outcompete or exclude species used for restoration. • Ecoystems may be free of unwanted plants and/or unwanted animals either because none ever existed naturally in the landscape or because they have been successfully minimized through management. • Examples of species that can impede restoration efforts include Brachiaria spp. in Brazil, Imperata cylindrica in Indonesia, Pueraria montana (kudzu) in southern United States, and uncontrolled grazing animals (cattle, sheep, goats) in multiple locations. | K23: • If “no”, then what are the persistent plant and/or animal species? | L23: ·
C24: 11. Native seeds, seedlings, or source populations are readily available | D24: • Does the target area have source populations, soil propagules bank (such as underground root systems and seed banks), or low-cost sources of native seeds and seedlings that can be the foundation for ecosystem recovery? | I24: The target area has natural sources that support regeneration, such as nearby natural areas, regrowth from underground roots, animal-dispersed seeds, and easy access to low-cost native seeds and seedlings that support ecosystem recovery. | J24: • Viable source populations or soil propagules bank of native plants are critically important for passive restoration. • This key success factor applies to the entire supply chain for native seeds and seedling, including seed production, seed collection and processing, and seedling nurseries. | K24: • If “no”, then where is the gap (e.g., seeds, seed collectors, nurseries, source populations, underground root systems)? | L24: ·
B25: f. Economic conditions | C25: 12.Competing economic demands for land (e.g., food, fuel) that drive land degradation are being managed | D25: • Are the economic pressures from crop, livestock, fuelwood, and/or biofuel production on degraded lands and natural ecosystems declining in the target area? | I25: Demand for crop, livestock, fuel wood, and/or biofuel production on degraded or natural ecosystems in the target area is declining (e.g., due to productivity improvements elsewhere), thereby reducing pressures that drive land degradation and “freeing up” opportunities for restoration. | J25: • Competing land-use pressures may come from agricultural expansion, infrastructure development, livestock grazing, fuel wood and urbanization. • This key success factor is arguably one of the most important in light of increasing global demand for land to produce crops, livestock, and biofuel (Searchinger et al. 2013). • This key factor would not apply when land is restored into agroforestry or silvopastoral systems which continue to produce crops and livestock, respectively. | K25: • What are the main alternative competing land uses for the candidate areas to be restored? | L25: ·
C26: 13. Value chains and/or market exist for commodity products (timber, agricultural products) and environmental products (carbon, water, biodiversity) from restored areas | D26: • Are value chains in place allowing products from restored land to reach end consumers? | I26: To the degree that forest restoration in the target area generates marketable products and services, value chains are in place allowing these products to get from the restored forest to the end consumer. | J26: • This key success factor refers to both market access and market demand for products and services derived from restored ecosystems. A “value chain” describes the multiple steps involved in offering a product or service such as harvesting, collection, processing, transportation, and distribution. A value chain from restoration suggests that individuals or groups in the target landscape can derive livelihoods and local economic activities as a part of restoring ecosystems. • Consider if there are initiatives, cooperatives or businesses in the target landscapes that sell products or services as a result of restoration activities. Are producers in these places able to differentiate their products and services through labels, certifications, or access to preferred markets? Is there infrastructure for processing and aggregating the products and services offered from the target landscapes? • Services from restored ecosystems could include recreation, tourism, and water provisioning. | K26: • If “no”, then where are the gaps in such a value chain? - If "yes," what is the value chain, including the producers, intermediaries, final consumers, etc. | L26: ·
B27: g. Policy conditions | C27: 14. Landusers, landholders or communities hold secure tenure rights to land and natural resources on the land | D27: • Do those who manage the target area have clear and secure rights to use land, harvest products sustainably, and receive financial benefits that would accrue from restoration? Are these rights accessible to all stakeholders, including women and vulnerable groups? | I27: People and communities who manage the target area have clear and secure rights (e.g., in the form of land ownership or natural resource management rights) to the benefits that would accrue from restoration. | J27: • Lack of (or insecure) land tenure and natural resource rights in the target area can discourage restoration that involves human intervention. People will not invest in planting trees and native vegetation or allow natural regeneration on lands they manage if they are unlikely benefit from the restored state. • Tenure and natural resource rights can take the form of private land ownership, communal lands, customary agreements, user-right certificates, etc. • Also consider whether the tenure that is in place overlaps or conflicts with customary rights. | K27: • If “no”, then what rights are missing, and for whom? | L27: ·
C28: 15. Policies affecting restoration are harmonized and streamlined | D28: • Are policies that may could impact restoration in the target area aligned and streamlined at a global, national, subnational and local context? | I28: Relevant public policies are aligned, coherent, and streamlined to effectively support restoration efforts in the target area. These policies are mutually reinforcing, minimize unnecessary administrative barriers, and create an enabling environment for implementation. Policies that promote gender equality and social inclusion are also considered integral to supporting inclusive and sustainable restoration outcomes. | J28: • National policies on climate, biodiversity, and land degradation will likely have points of overlap for restoration that can be considered through existing national committees. • Other policies to consider include those on agriculture, extractive industries, water, land use planning, infrastructure and natural resources. • In some cases, policies for nature conservation or other sectors may inhibit restoration (e.g., laws forbidding extraction of native seeds from protected areas, laws forbidding harvesting native tree species, subsidies that encourage to drivers of degradation). | K28: • If “no”, then which policies are not aligned or streamlined? | L28: ·
C29: 16. Restrictions on clearing remaining natural ecosystems (e.g., forests, grasslands, wetlands) exist | D29: • Does the target area have laws restricting the clearing or cutting of remaining natural ecosystems? | I29: The target area has laws restricting clearing or cutting of remaining natural ecosystems. | J29: • Restrictions on clearing remaining natural forests and ecosystems can prevent further expansion of degraded or cleared areas. These restrictions also create an incentive to restore the productivity of already cleared areas since opportunities to use the forest frontier are reduced. • Restrictions can also take the form of an extensive network of national parks and national forests, an extensive network of forested indigenous territories, ecosystem protection rules on communal lands, “no net loss” rules, specific percentages of land required to remain as forest (e.g., Brazil’s Forest Code) and more. • An important component of this key success factor is that “natural forests and ecosystems” have been clearly defined by the jurisdiction sponsoring the restriction (e.g., national government). This definition should include primary forests, secondary forests, and degraded forests and other ecosystems with potential for restoration. | K29: • If “yes”, then what are those laws? | L29: ·
C30: 17. Restrictions on clearing remaining natural ecosystems (e.g., forests, grasslands, wetlands) are enforced | D30: • Are these clearing or cutting restrictions adequately enforced? | I30: Laws that restrict clearing of remaining natural ecosystems are adequately enforced. | J30: • It is not sufficient that regulations restricting clearing of remaining natural ecosystems merely exist; the restrictions need to be enforced by relevant authorities. • Particularly in remote areas, enforcement depends on the capacity of law enforcement organizations and incentives for them to exercise enforcement activities. | K30: • If “no”, then why not? | L30: ·
B31: h. Social and cultural conditions | C31: 18. Women, youth, and Indigenous Peoples participate in restoration decision making | D31: • Are women, youth, and Indigenous Peoples living in and around the target area—along with the cultural systems, traditional governance structures, and knowledge systems they represent—meaningfully involved in restoration decision-making (e.g., program design, goal-setting, management, monitoring, and indicator selection)? | I31: Women, youth, and Indigenous Peoples are explicitly recognized and supported as key participants in restoration planning and implementation at all scales. Their cultural systems, traditional governance structures, and knowledge are respected and integrated into decision-making bodies, governance arrangements, and monitoring processes, ensuring inclusive, representative, and culturally appropriate restoration outcomes. | J31: • Decision-making related to areas—including planning, design, management, and monitoring—should be inclusive and culturally appropriate. Where participation is limited or extractive, restoration efforts risk fragmented uptake, weakened local ownership, and inequitable distribution of benefits, particularly for women, youth, and Indigenous Peoples. • Leveraging and strengthening existing local institutions and culturally grounded processes (e.g., village-based forestry cooperatives, women’s groups, Indigenous Peoples’ organizations, youth associations, and traditional governance systems) can support co-management arrangements, enhance local participation, and increase long-term adoption of restoration efforts. • Restoration planning and implementation should recognize and respect cultural systems more broadly—including the values, knowledge, and practices of diverse stakeholder groups—and integrate these perspectives into decision-making, management, and monitoring processes. • Effective and inclusive participation requires transparency and accountability in decision-making, respect for Free, Prior, and Informed Consent (FPIC) where applicable, and accessible, trusted grievance and feedback mechanisms that allow stakeholders to raise concerns and enable course correction when processes or outcomes fall short. | K31: • If “no”, then what aspects are people not empowered to do? - If "no" which groups aren´t properly represented? | L31: ·
C32: 19. Local people benefit from restoration | D32: • Are people living in and around the target area able to capture or enjoy the benefits generated by restoration, such as improved livelihoods or ecosystem services? | I32: Communities who live in or around the target areas have their needs addressed from restoration efforts and receive environmental benefits (e.g., improved water quality, increased supply of forest products) or economic benefits (e.g., alternate sources of income, improved livelihoods) from restoration. | J32: • The planning documentation and technical design of any restoration initiative should include frameworks and mechanisms to ensure that people living in or adjacent to the restored area(s) are the primary beneficiaries of the positive outcomes of restoration. Examples of the types of benefits restoration can produce are available here. • Restoration planners or implementers should continually ask themselves: Among the social, cultural, political, environmental, and economic benefits identified, do restoration plans specify which local people or groups are expected to benefit from restoration activities? Do these benefits correspond with local needs? Are the benefits received by local people in a reasonable, equitable, and reliable way? • If local people do not perceive benefits, then they will have little incentive to change behaviors to enable restoration or sustain the restored ecosystem over the long term. | K32: • If “no”, then why not? | L32: ·
B33: i. Institutional conditions | C33: 20. Roles and responsibilities for restoration are clearly defined | D33: • Are the roles and responsibilities for ecosystem restoration in the target area clearly defined, understood by relevant actors, and accompanied by authority, and, when necessary, conflict-resolution mechanisms exist? | I33: Roles and responsibilities for restoration in the target area are clearly defined, understood among relevant actors (e.g., government, civil society, private sector and others relevant stakeholders), and accompanied by authority. And conflict resolution mechanisms exist and are implemented | J33: • Consider whether there are designated agencies, institutions, or groups with the power to implement ecosystem restoration. • In the absence of clarity on roles and responsibilities, inaction may occur due to important roles not being filled, uncertainty about who does what, or due to institutions and groups claiming overlapping responsibility and rights. • To adequately answer this question, users may need to map out existing mandates for restoration planning, coordination, implementation and monitoring among public entities, private groups and organizations, land owners, land users, and other key stakeholders. Roles, responsibilities and rights can also be defined in laws, policies or customary practices. • Conflict resolution mechanisms for ecosystem restoration are structured, collaborative systems designed to manage disputes between stakeholders regarding the management, access, and use of natural resources or other activities during restoration projects. | K33: • If “no”, then what is missing in terms of clarity of roles and responsibilities? | L33: ·
C34: 21.Effective institutional coordination is ongoing | D34: • Are relevant stakeholders from government, civil society, and the private sector effectively coordinated—such as through a working group or multistakeholder process—to design, implement, and monitor ecosystem restoration in the candidate area, while also ensuring that these efforts are inclusive of vulnerable groups? | I34: Relevant actors from government, civil society, and/or the private sector are sufficiently coordinated to design, implement, and monitor restoration in the target area. | J34: • Consider whether public and private institutions have committed to clear leadership and mandates for restoration. Is there demonstrated joint action in the form of coordination mechanisms, committees, working groups or alliances that meet regularly and make decisions about restoration? Do these coordination efforts include shared plans, data, technical input, and monitoring, especially across local, regional and national levels of governance? | K34: • If “no”, then what is missing in terms of coordination? | L34: ·
B35: Enabling condition | C35: Key Factor | D35: Diagnostic question | E35: Response | F35: National | G35: Regional | H35: Local | J35: Guidance for the diagnostic question | K35: Follow up question(s) | L35: Follow up responses, rationale and supporting documents
A36: Implement | B36: j. Leadership | C36: 22. National and/or local restoration champions exist | D36: • Is there a charismatic, committed champion(s) of restoration for the target area? Do they represent all stakeholders in society, including women, youth, and Indigenous peoples? | I36: Charismatic people (or powerful institutions) exist who can effectively inspire decision makers to pursue restoration, mobilize support, and maintain momentum over time in the candidate area . | J36: • Champions can be individuals or groups who are committed to ecosystems restoration, and able to act upon these commitments. In some landscapes or ecosystmes, champions may need to be cultivated and given a visible profile. • Historically, successful examples of restoration had either a champion or strong government support. Few lacked both. | K36: • Who is the champion(s)?
C37: 23. Sustained political commitment exists | D37: • Is there clear and sustained long-term commitment from government and non-governmental institutions to support restoration efforts in the target area, including allocated budgets? | I37: Commitment from government authorities (across relevant levels, where applicable) and non-governmental institutions to restoration in the target area is clearly established and recognized as a sustained, long-term commitment and allocated budget. | J37: • It may be difficult to predict the long-term commitment of a government or organization. In such situations, consider whether the commitment transcends political parties and whether the restoration will produce recurring benefits for key stakeholders. • Government restoration goals could be supported by dedicated public funding. When reviewing, check whether the targets have a clear budget or funding mechanism attached to them, indicating real and sustained demand or if there is a finance plan. | K37: • If “yes”, what is the proof of the expressed commitment, and from whom?
B38: k. Knowledge | C38: 24. Restoration "know how" relevant to candidate geographies exist | D38: • Does diverse local knowledge exist (including Indigenous, traditional ecological knowledge, and gender-informed knowledge) on how to implement restoration at scale in the target area? | I38: Local experts know of -- or generate research on -- restoration techniques (e.g., natural and assisted regeneration, traditional knowledge) tailored to the candidate area. | J38: • Local expertise can come from traditional knowledge from communities living in or around the landscape, experts from universities and rural extension services, and nongovernmental organizations active in the field. • The know-how may be generated locally or might be imported from elsewhere but should be communicated or delivered by local practitioners. “Best practice” guidance on restoration may be available from universities, nongovernmental organizations, or extension agencies, as well as from local individuals or groups with long-term restoration expertise. | K38: • If “no”, then what are the most important knowledge gaps?
C39: 25. Restoration "know how" is transferred via peers or extension services | D39: • Are extension services, farmer-to-farmer visits, women’s groups, local networks and/or other means of awareness raising and capacity building for restoration in place, and adequately resourced in the target area or at national level? | I39: Technical assistance and rural extension (“extension services”), farmer-to-farmer visits, women's groups, local networks and/or other means of awareness raising and capacity building for restoration are in place and adequately resourced in the candidate area. | J39: • Knowledge sharing may be documented in formal extension services like field visits, training programs, field schools, printed materials and demonstration sites. • Consider whether informal learning groups on restoration are sharing information or coordinating activities, including women’s groups, producer associations, or knowledge exchange among Indigenous Peoples. This “Farmer-to-farmer” or “land-manager-to-land-manager” communication can be one of the most effective means of education and training. • Local networks or partnerships for capacity building on ecosystem restoration, agroforestry, or reforestation may be reported in national documents or reports by nongovernmental organizations. | K39: • For the candidate landscape, which entities are best positioned to deliver extension services?
B40: l.Technical design | C40: 26. Restoration design is technically grounded and climate resilient | D40: • Is the restoration plan for the target area based on best practices, incorporating the best available science, traditional ecological knowledge, and climate resilient approaches? | I40: The restoration plan for the candidate area is based on best practices for design, implementation, and maintenance of restoration actvities. The restoration plan incorporates the best available science and climate resilient approaches that ensure the intervention, including aspects such as species selection and restoration techniques, is appropriate for the local context and goals of the intervention, and reduce vulnerability of the restoration intervention to climate impacts such as drought, flood, wildfires, and extreme temperatures. | J40: • Consider whether the approaches for ecosystem restoration are supported by scientific research, local knowledge, or Indigenous practices for recovering natural ecosystems and reducing vulnerability to climate impacts. • Technical design should address aspects such as site preparation, slope, species selection, tree spacing, and maintenance, or how to remove pressures preventing natural vegetation from regrowing (e.g., livestock, fire). • Restoration plans should factor in projected climate impacts in order to be climate resilient. | K40: • If “no”, then what is missing from the plan?
C41: 27. Restoration limits "leakage" | D41: • Does the restoration process have provisions in place (e.g., policies, practices, incentives, yield improvements) that limit leakage or is unfolding in a manner that reduces leakage? Do restoration activities avoid displacement of landusers to other areas where they have no option but to transform/clear natural ecosystems for agricultural land uses? | I41: Ecosystem restoration in the candidate area avoids transferring land clearing activities to other locations (“leakage”), resulting in net increase of restored area. | J41: • There is a risk that ecosystem restoration in the target area could result in displacing the activities that were causing land degradation to some other landscape. • While such “leakage” might result in an increase in the amount of restored area in the target landscape, it would result in an increase of degraded or deforested lands elsewhere. • Ways to limit leakage of restoration activities could include: Combining restoration with productive uses (e.g., agroforestry), providing local livelihood alternatives that do not require converting lands into agriculture, increasing agricultural efficiency so output doesn’t move to new areas, planning restoration at the landscape level to manage where activities shift and addressing underlying drivers of degradation. • For more information on reforestation in one country displacing deforestation to another country to another see: Meyfroidt and Lambin (2011). | K41: • If “no”, then what measures are missing from the restoration process to avoid displacement of land degradation to other areas?
B42: m. Finance and incentives | C42: 28. Positive incentives and funds for restoration outweigh negative incentives | D42: • From the perspective of relevant stakeholders, do available financial incentives and funding mechanisms sufficiently encourage restoration in the target area, relative to incentives that may discourage or impede ecosystem recovery? | I42: From the perspective of relevant stakeholders, financial incentives and funding mechanisms to support restoration in the candidate area are available, accessible, and sufficiently attractive to encourage investment in restoration activities. These incentives are designed to offset opportunity costs and financial risks associated with restoration, and to outweigh competing incentives that favor land uses or practices that hinder or delay ecosystem recovery. The overall incentive framework supports sustained engagement in restoration over the long term. | J42: • Restoration can occur when overall incentives outweigh both the costs of restoration and the ongoing benefits occurring on the degraded landscape. • “Positive” incentives (e.g., grants, loans, tax breaks, subsidies, ecosystem service payments, private goods and services) encourage restoration, while “negative” incentives (e.g., subsidies for livestock, agriculture, or extractive industries) discourage restoration. • If the positive incentives are overshadowed by negative incentives, large-scale restoration is unlikely; and both the amount and timing of incentives matter. • Incentives and finance are part of implementation because they directly affect land managers’ decisions to restore. • Corporate commitments can also be analyzed for the proposed area, they refer to pledges by companies to restore ecosystems or meet climate and biodiversity targets. When reviewing, check whether these commitments are specific, measurable, and linked to concrete actions or financing for restoration. | K42: • What are the relevant positive and negative incentives? • What is the scale of these incentives from a land manager’s perspective (e.g., $/hectare)?
C43: 29. Finance is available for restoration actions | D43: • Are the financial incentives and funding mechanisms aimed at promoting restoration in the target area accessible, inclusive, and usable by a diverse range of stakeholders, including local communities, while also ensuring long-term sustainability? | I43: Financial mechanisms and incentives have been thoughtfully designed, selected, and implemented to effectively support restoration policies, actions, and measures at both landscape and community scales. These mechanisms are accessible to a wide range of stakeholders, promote equitable participation, and leverage private sector finance where appropriate to enhance and sustain restoration outcomes. Long-term funding refers to financial resources that are committed to support activities over an extended period of time, ensuring continuity and stability. | J43: • Incentives and funds include grants, loans, tax breaks on the inputs, outputs, or financing of restoration, direct government expenditures like subsidies or procurement policies, payments for ecosystem services, or private markets for goods and services that encourage ecosystem restoration efforts. • Consider whether individuals, communities, or groups in the restoration area(s) have applied to and received financial support for restoration activities. Include feedback from the individuals or groups who have tried to access these incentives or funds but were not successful. • Long-term funding and market mechanisms refer to sustained financial support for activities over time, including dedicated funding sources or systems that generate ongoing demand, such as environmental credit markets. When reviewing, check whether there are multi-year funding commitments or market-based instruments that can reliably support implementation. | K43: • If “no”, then what are the barriers to access?
B44: n. Feedback | C44: 30. Effective monitoring and evaluation system is in place | D44: • Is there a monitoring system in place for tracking and evaluating restoration progress at the relevant area or national level, and does it align with the national and global monitoring systems? | I44: A system for monitoring progress and evaluating impact of restoration in the candidate area exists. | J44: • Information for monitoring and evaluation should be gathered in a planned, ongoing way to provide insight and feedback on the implementation of restoration activities. Aspects to monitor may include hectares under restoration, survival rates of planted species, quantified economic and social benefits, and ecosystem service flows. • Monitoring and evaluation systems may employ approaches such as remote sensing, crowd-sourced ground-level monitoring (e.g., using community, volunteers, and communication technologies), and surveys of inhabitants of the target area . | K44: • If “yes”, is baseline data already being gathered? • If “no”, what aspects of a performance monitoring system are missing?
C45: 31.Early and ongoing suceesses are communicated | D45: • Are restoration successes being communicated in the target area and the target audience being identified? | I45: Key successes in restoring the candidate area are promptly shared with stakeholders, ensuring they are informed of the progress and fostering a sense of partnership and engagement. | J45: • Communication may take the form of documentation and story coverage in media campaigns and social media, but may also include direct observation via visits of farmers, land managers, and decision makers to restoration sites. • Achieving and publicly communicating success, including “early wins” can help maintain momentum, recruit more engagement, trigger replication elsewhere in the landscape, shore up political support, and sustain external financing. | K45: • If “yes”, how are the successes communicated (e.g., through what media)? • If “no”, what media are available that could be utilized?

Sheet Step 3. Propose Actions
A1: Step 3. Select strategic actions to address gaps in key factors
B3: Purpose Step 3 will help you design strategies to address the key factors that are missing or only partly in place. The aim is to identify actions that increase the likelihood of successful restoration in the target geography. Identifying Strategies Users brainstorm and record ideas from the example categories below that can be used to improve missing or weak success factors: • Policies • Incentives • Institutional reforms • Capacity-building actions • Cross-sectoral interventions (e.g., agriculture, finance, land tenure) Key considerations: • One strategy may address multiple gaps • Strategies should clearly specify: • Who will act • What will be done • Why • By when • How, including how actions will be funded Examples of strategies are provided in the tool, but these are illustrative, not prescriptive. Local context and judgment are essential.
B5: Enabling condition | C5: Key Factor | D5: Response | E5: Strategies to address gap in enabling factor | F5: National | G5: Regional | H5: Local | I5: Examples of strategies to address gap in key factor
A6: Motivate | B6: a. Benefits | C6: 1. Restoration generates economic benefits | D6: =IF(ISBLANK('Step 2. Assess Key Factors'!E13),"",'Step 2. Assess Key Factors'!E13) | E6: · | I6: • Conduct a benefit-cost analysis comparing (a) likely benefits generated from the restored landscape, (b) likely costs of restoring the target landscape, and (c) likely costs and benefits of the status quo use of the landscape.
C7: 2. Restoration generates social benefits | D7: =IF(ISBLANK('Step 2. Assess Key Factors'!E14),"",'Step 2. Assess Key Factors'!E14) | E7: · | I7: • Engage communities living in and around the target area to identify their social, political, or cultural goals and priorities. This could be done through surverys or in-person workshops. Based on this exercise, co-create a map of restoration interventions that could help achieve these goals. • Validate existing restoration plans, financing instruments, monitoring systems, and indicators with local communities, including respresentatives from vulnerable populations, to ensure plans serve community needs.
C8: 3. Restoration generates environmental benefits | D8: =IF(ISBLANK('Step 2. Assess Key Factors'!E15),"",'Step 2. Assess Key Factors'!E15) | E8: · | I8: • Engage scientists (e.g., biologists, ecologists, hydrologists, soil scientists) to identify which environmental benefits could be generated from restoration efforts.
B9: b. Awareness | C9: 4. Benefits of restoration are publicly communicated | D9: =IF(ISBLANK('Step 2. Assess Key Factors'!E16),"",'Step 2. Assess Key Factors'!E16) | E9: · | I9: • Produce awareness-raising materials and campaigns via newspapers, radio, television, internet, and/or site visits, depending on the target audience • Introduce and/or leverage existing national restoration activities such as public or school tree planting programs.
C10: 5. Opportunities for restoration are identified | D10: =IF(ISBLANK('Step 2. Assess Key Factors'!E17),"",'Step 2. Assess Key Factors'!E17) | E10: · | I10: • Conduct a “Restoration Opportunities Assessment Methodology” planning activity. This is a comprehensive restoration planning resource available online https://iucn.org/resources/grey-literature/guide-restoration-opportunities-assessment-methodology-roam
B11: c. Crisis events | C11: 6. Crisis events are leveraged | D11: =IF(ISBLANK('Step 2. Assess Key Factors'!E18),"",'Step 2. Assess Key Factors'!E18) | E11: · | I11: • Conduct and communicate research that quantifies and visualizes the extent to which restored ecosystems can prevent or mitigate natural humanitarian disasters and save money on mitigation efforts when proper planning and prevention are implemented. • When disasters occur, immediately publicly communicate the benefits of restoration.
B12: d. Legal requirements | C12: 7. Laws and policies requiring restoration exist | D12: =IF(ISBLANK('Step 2. Assess Key Factors'!E19),"",'Step 2. Assess Key Factors'!E19) | E12: · | I12: • Establish government law (or industry policy) that requires land managers to allow vegetation recovery or to replant vegetation in areas that have been cleared due to their own commercial activity (e.g., logging, mining, etc.).
C13: 8. Laws and policies requiring restoration are broadly understood and enforced | D13: =IF(ISBLANK('Step 2. Assess Key Factors'!E20),"",'Step 2. Assess Key Factors'!E20) | E13: · | I13: • Conduct communication campaign to make relevant actors aware of restoration requirements. • Take enforcement action (e.g., fines, denial of credit access, jail) against violations of restoration requirements. • Ensure human and financial resources for enforcement are adequate.
B14: Enabling condition | C14: Key Factor | D14: =IF(ISBLANK('Step 2. Assess Key Factors'!E21),"",'Step 2. Assess Key Factors'!E21) -> Response | E14: Strategies to address gap in enabling factor | F14: National | G14: Regional | H14: Local | I14: Examples of strategies to address gap in key factor
